Workbook

Sheet Accueil RNCP
B6: Grille d'évaluation
B9: Présentation de la grille d'évaluation
B10: Cette grille d'évaluation a pour but de vous aider dans votre notation. Elle est utilisée pour les évaluations dites "validante de blocs". Pour info : Les cellules en bleu et jaune sont vérouillées pour éviter les erreurs de saisies.
B15: Configuration
B16: Afin de faliciliter la notation par critères (liés au titre RNCP), vous devez appliquer un coefficient par modalité (colonne E ci-dessous). Vous pouvez ensuite modifier les critères de 1 à 5 dans la feuille "Grille d'évaluation" pour que cette grille d'évaluation soit en adéquation parfaite avec votre matière. La configuration est maintenant terminée, vous pouvez maintenant appliquer les notes à vos groupes en indiquant les étudiants membres de celui-ci.
B25: BLOC RNCP | D25: 5
B26: Matière | D26: Introduction aux traitements distribués
B27: Jury
B28: Formateur
B30: Modalité | C30: Critère | D30: Description | E30: Coeff. | F30: %
B31: 1 | C31: 1 | D31: Le candidat automatise la mise en place de l'architecture. | E31: 2 | F31: =IF(E31<>"",E31/SUM(E$31:E$42),"") -> 0.25
B32: 1 | C32: 2 | D32: Le candidat produit les tests de sécurité adaptés à l'application et documente les anomalies identifiées. | E32: 2 | F32: =IF(E32<>"",E32/SUM(E$31:E$42),"") -> 0.25
B33: 1 | C33: 3 | D33: Le candidat préconise les outils de protection adaptés aux risques identifiés. | E33: 2 | F33: =IF(E33<>"",E33/SUM(E$31:E$42),"") -> 0.25
B34: 1 | C34: 4 | D34: Le candidat produit les documentations techniques et d'usages nécessaires au développement ultérieur de la solution. | E34: 1 | F34: =IF(E34<>"",E34/SUM(E$31:E$42),"") -> 0.125
B35: 1 | C35: 5 | D35: Le candidat définit un protocole de validation et élabore le cahier de recette. | E35: 1 | F35: =IF(E35<>"",E35/SUM(E$31:E$42),"") -> 0.125
F36: =IF(E36<>"",E36/SUM(E$31:E$42),"")
F37: =IF(E37<>"",E37/SUM(E$31:E$42),"")
F38: =IF(E38<>"",E38/SUM(E$31:E$42),"")
F39: =IF(E39<>"",E39/SUM(E$31:E$42),"")
F40: =IF(E40<>"",E40/SUM(E$31:E$42),"")
F41: =IF(E41<>"",E41/SUM(E$31:E$42),"")
F42: =IF(E42<>"",E42/SUM(E$31:E$42),"")

Sheet Grille d'évaluation
A1: Groupe | B1: Étudiants | C1: Notes de groupe | N1: Notes individuelles | R1: Total | S1: Avis formateur | T1: Points forts | U1: Points faibles | W1: Note individuelle | X1: =IF(ISBLANK('Accueil RNCP'!D31),"N.C.",_xlfn.CONCAT("Critère ",'Accueil RNCP'!$B$31,".",'Accueil RNCP'!$C$31)) -> Critère 1.1 | Y1: =IF(ISBLANK('Accueil RNCP'!D32),"N.C.",_xlfn.CONCAT("Critère ",'Accueil RNCP'!$B$32,".",'Accueil RNCP'!$C$32)) -> Critère 1.2 | Z1: =IF(ISBLANK('Accueil RNCP'!D33),"N.C.",_xlfn.CONCAT("Critère ",'Accueil RNCP'!$B$33,".",'Accueil RNCP'!$C$33)) -> Critère 1.3 | AA1: =IF(ISBLANK('Accueil RNCP'!D34),"N.C.",_xlfn.CONCAT("Critère ",'Accueil RNCP'!$B$34,".",'Accueil RNCP'!$C$34)) -> Critère 1.4 | AB1: =IF(ISBLANK('Accueil RNCP'!D35),"N.C.",_xlfn.CONCAT("Critère ",'Accueil RNCP'!$B$35,".",'Accueil RNCP'!$C$35)) -> Critère 1.5 | AC1: =IF(ISBLANK('Accueil RNCP'!D36),"N.C.",_xlfn.CONCAT("Critère ",'Accueil RNCP'!$B$36,".",'Accueil RNCP'!$C$36)) -> N.C. | AD1: =IF(ISBLANK('Accueil RNCP'!D37),"N.C.",_xlfn.CONCAT("Critère ",'Accueil RNCP'!$B$37,".",'Accueil RNCP'!$C$37)) -> N.C. | AE1: =IF(ISBLANK('Accueil RNCP'!D38),"N.C.",_xlfn.CONCAT("Critère ",'Accueil RNCP'!$B$38,".",'Accueil RNCP'!$C$38)) -> N.C. | AF1: =IF(ISBLANK('Accueil RNCP'!D39),"N.C.",_xlfn.CONCAT("Critère ",'Accueil RNCP'!$B$39,".",'Accueil RNCP'!$C$39)) -> N.C. | AG1: =IF(ISBLANK('Accueil RNCP'!D40),"N.C.",_xlfn.CONCAT("Critère ",'Accueil RNCP'!$B$40,".",'Accueil RNCP'!$C$40)) -> N.C. | AH1: =IF(ISBLANK('Accueil RNCP'!D41),"N.C.",_xlfn.CONCAT("Critère ",'Accueil RNCP'!$B$41,".",'Accueil RNCP'!$C$41)) -> N.C. | AI1: =IF(ISBLANK('Accueil RNCP'!D42),"N.C.",_xlfn.CONCAT("Critère ",'Accueil RNCP'!$B$42,".",'Accueil RNCP'!$C$42)) -> N.C. | AJ1: Moy. | AN1: =W1 -> Note individuelle | AO1: =X1 -> Critère 1.1 | AP1: =Y1 -> Critère 1.2 | AQ1: =Z1 -> Critère 1.3 | AR1: =AA1 -> Critère 1.4 | AS1: =AB1 -> Critère 1.5 | AT1: =AC1 -> N.C. | AU1: =AD1 -> N.C. | ... BA1: =AJ1 -> Moy.
C2: Niveau d’expertise & Défi technique | D2: Qualité de la soutenance Visuels, textes, gestion globale du temps | E2: Cohésion du groupe Organisation du temps de parole, homogénéité | F2: Critères matière | N2: Complexité et réalisation de la tâche allouée | O2: Contribution à la soutenance Clareté, expression, apport au groupe | P2: Interaction avec le jury Réponses et explications | Q2: Bonus / Malus Exploit, malhonnêteté, absence
F3: Algorithmes | G3: Enjeux de sécurité | H3: Mise en production | I3: Adéquation avec le cas | X3: =IF('Accueil RNCP'!E31<>"",'Accueil RNCP'!E31/SUM('Accueil RNCP'!E$31:E$42),"") -> 0.25 | Y3: =IF('Accueil RNCP'!E32<>"",'Accueil RNCP'!E32/SUM('Accueil RNCP'!E$31:E$42),"") -> 0.25 | Z3: =IF('Accueil RNCP'!E33<>"",'Accueil RNCP'!E33/SUM('Accueil RNCP'!E$31:E$42),"") -> 0.25 | AA3: =IF('Accueil RNCP'!E34<>"",'Accueil RNCP'!E34/SUM('Accueil RNCP'!E$31:E$42),"") -> 0.125 | AB3: =IF('Accueil RNCP'!E35<>"",'Accueil RNCP'!E35/SUM('Accueil RNCP'!E$31:E$42),"") -> 0.125 | AC3: =IF('Accueil RNCP'!E36<>"",'Accueil RNCP'!E36/SUM('Accueil RNCP'!E$31:E$42),"") | AD3: =IF('Accueil RNCP'!E37<>"",'Accueil RNCP'!E37/SUM('Accueil RNCP'!E$31:E$42),"") | AE3: =IF('Accueil RNCP'!E38<>"",'Accueil RNCP'!E38/SUM('Accueil RNCP'!E$31:E$42),"") | AF3: =IF('Accueil RNCP'!E39<>"",'Accueil RNCP'!E39/SUM('Accueil RNCP'!E$31:E$42),"") | AG3: =IF('Accueil RNCP'!E40<>"",'Accueil RNCP'!E40/SUM('Accueil RNCP'!E$31:E$42),"") | AH3: =IF('Accueil RNCP'!E41<>"",'Accueil RNCP'!E41/SUM('Accueil RNCP'!E$31:E$42),"") | AI3: =IF('Accueil RNCP'!E42<>"",'Accueil RNCP'!E42/SUM('Accueil RNCP'!E$31:E$42),"") | AL3: MIN | AM3: MAX
C4: 4 | D4: 2 | E4: 1 | F4: 4 | G4: 4 | H4: 4 | I4: 4 | J4: 0 | K4: 0 | L4: 0 | M4: 0 | N4: 4 | O4: 1 | P4: 2
A5: 1 | R5: =ROUNDDOWN(2*(SUMPRODUCT(C$4:P$4,C5:P5)/SUM(C$4:P$4)*20+Q5),0)/2 -> 0 | W5: =IF(COUNT(C5:Q5)>0,ROUND(2*SUM(N5:Q5)/7*20,0)/2,"") | X5: =IF(AND(X$3<>"",$W5<>""),ROUND(2*($R5*(COUNT($X$3:$AI$3)+1)-$W5)*X$3,0)/2,"") | Y5: =IF(AND(Y$3<>"",$W5<>""),ROUND(2*($R5*(COUNT($X$3:$AI$3)+1)-$W5)*Y$3,0)/2,"") | Z5: =IF(AND(Z$3<>"",$W5<>""),ROUND(2*($R5*(COUNT($X$3:$AI$3)+1)-$W5)*Z$3,0)/2,"") | AA5: =IF(AND(AA$3<>"",$W5<>""),ROUND(2*($R5*(COUNT($X$3:$AI$3)+1)-$W5)*AA$3,0)/2,"") | AB5: =IF(AND(AB$3<>"",$W5<>""),ROUND(2*($R5*(COUNT($X$3:$AI$3)+1)-$W5)*AB$3,0)/2,"") | AC5: =IF(AND(AC$3<>"",$W5<>""),ROUND(2*($R5*(COUNT($X$3:$AI$3)+1)-$W5)*AC$3,0)/2,"") | AD5: =IF(AND(AD$3<>"",$W5<>""),ROUND(2*($R5*(COUNT($X$3:$AI$3)+1)-$W5)*AD$3,0)/2,"") | AE5: =IF(AND(AE$3<>"",$W5<>""),ROUND(2*($R5*(COUNT($X$3:$AI$3)+1)-$W5)*AE$3,0)/2,"") | ... AI5: =IF(AND(AI$3<>"",$W5<>""),ROUND(2*($R5*(COUNT($X$3:$AI$3)+1)-$W5)*AI$3,0)/2,"") | AJ5: =IF(COUNT(W5:AI5)>0,ROUND(2*AVERAGE(W5:AE5),0)/2,"") | AL5: =IF(R5<10,MAX(0,2*R5-10),MAX(10,2*R5-20)) -> 0 | AM5: =2*R5-AL5 -> 0 | AN5: =IF(W5<>"",MIN($AM5,MAX($AL5,IF($AJ5>0,0.5*ROUNDUP(2*((W5-MIN($W5:$AI5))/(MAX($W5:$AI5)-MIN($W5:$AI5))*($AM5-$AL5+IF(Q5>10,1,0))+$AL5),0),0))),"") | AO5: =IF(X5<>"",MIN($AM5,MAX($AL5,IF($AJ5>0,0.5*ROUNDUP(2*((X5-MIN($W5:$AI5))/(MAX($W5:$AI5)-MIN($W5:$AI5))*($AM5-$AL5+IF(R5>10,1,0))+$AL5),0),0))),"") | AP5: =IF(Y5<>"",MIN($AM5,MAX($AL5,IF($AJ5>0,0.5*ROUNDUP(2*((Y5-MIN($W5:$AI5))/(MAX($W5:$AI5)-MIN($W5:$AI5))*($AM5-$AL5+IF(S5>10,1,0))+$AL5),0),0))),"") | AQ5: =IF(Z5<>"",MIN($AM5,MAX($AL5,IF($AJ5>0,0.5*ROUNDUP(2*((Z5-MIN($W5:$AI5))/(MAX($W5:$AI5)-MIN($W5:$AI5))*($AM5-$AL5+IF(T5>10,1,0))+$AL5),0),0))),"") | AR5: =IF(AA5<>"",MIN($AM5,MAX($AL5,IF($AJ5>0,0.5*ROUNDUP(2*((AA5-MIN($W5:$AI5))/(MAX($W5:$AI5)-MIN($W5:$AI5))*($AM5-$AL5+IF(U5>10,1,0))+$AL5),0),0))),"") | AS5: =IF(AB5<>"",MIN($AM5,MAX($AL5,IF($AJ5>0,0.5*ROUNDUP(2*((AB5-MIN($W5:$AI5))/(MAX($W5:$AI5)-MIN($W5:$AI5))*($AM5-$AL5+IF(V5>10,1,0))+$AL5),0),0))),"") | AT5: =IF(AC5<>"",MIN($AM5,MAX($AL5,IF($AJ5>0,0.5*ROUNDUP(2*((AC5-MIN($W5:$AI5))/(MAX($W5:$AI5)-MIN($W5:$AI5))*($AM5-$AL5+IF(W5>10,1,0))+$AL5),0),0))),"") | AU5: =IF(AD5<>"",MIN($AM5,MAX($AL5,IF($AJ5>0,0.5*ROUNDUP(2*((AD5-MIN($W5:$AI5))/(MAX($W5:$AI5)-MIN($W5:$AI5))*($AM5-$AL5+IF(X5>10,1,0))+$AL5),0),0))),"") | ... AZ5: =IF(AI5<>"",MIN($AM5,MAX($AL5,IF($AJ5>0,0.5*ROUNDUP(2*((AI5-MIN($W5:$AI5))/(MAX($W5:$AI5)-MIN($W5:$AI5))*($AM5-$AL5+IF(AC5>10,1,0))+$AL5),0),0))),"") | BA5: =IF(ISNUMBER(AJ5),ROUND(2*AVERAGE(AN5:AZ5),0)/2,"")
R6: =ROUNDDOWN(2*(SUMPRODUCT(C$4:P$4,C6:P6)/SUM(C$4:P$4)*20+Q6),0)/2 -> 0 | W6: =IF(COUNT(D6:Q6)>0,ROUND(2*SUM(N6:Q6)/7*20,0)/2,"") | X6: =IF(AND(X$3<>"",$W6<>""),ROUND(2*($R6*(COUNT($X$3:$AI$3)+1)-$W6)*X$3,0)/2,"") | Y6: =IF(AND(Y$3<>"",$W6<>""),ROUND(2*($R6*(COUNT($X$3:$AI$3)+1)-$W6)*Y$3,0)/2,"") | Z6: =IF(AND(Z$3<>"",$W6<>""),ROUND(2*($R6*(COUNT($X$3:$AI$3)+1)-$W6)*Z$3,0)/2,"") | AA6: =IF(AND(AA$3<>"",$W6<>""),ROUND(2*($R6*(COUNT($X$3:$AI$3)+1)-$W6)*AA$3,0)/2,"") | AB6: =IF(AND(AB$3<>"",$W6<>""),ROUND(2*($R6*(COUNT($X$3:$AI$3)+1)-$W6)*AB$3,0)/2,"") | AC6: =IF(AND(AC$3<>"",$W6<>""),ROUND(2*($R6*(COUNT($X$3:$AI$3)+1)-$W6)*AC$3,0)/2,"") | AD6: =IF(AND(AD$3<>"",$W6<>""),ROUND(2*($R6*(COUNT($X$3:$AI$3)+1)-$W6)*AD$3,0)/2,"") | AE6: =IF(AND(AE$3<>"",$W6<>""),ROUND(2*($R6*(COUNT($X$3:$AI$3)+1)-$W6)*AE$3,0)/2,"") | ... AI6: =IF(AND(AI$3<>"",$W6<>""),ROUND(2*($R6*(COUNT($X$3:$AI$3)+1)-$W6)*AI$3,0)/2,"") | AJ6: =IF(COUNT(W6:AI6)>0,ROUND(2*AVERAGE(W6:AE6),0)/2,"") | AL6: =IF(R6<10,MAX(0,2*R6-10),MAX(10,2*R6-20)) -> 0 | AM6: =2*R6-AL6 -> 0 | AN6: =IF(W6<>"",MIN($AM6,MAX($AL6,IF($AJ6>0,0.5*ROUNDUP(2*((W6-MIN($W6:$AI6))/(MAX($W6:$AI6)-MIN($W6:$AI6))*($AM6-$AL6+IF(Q6>10,1,0))+$AL6),0),0))),"") | AO6: =IF(X6<>"",MIN($AM6,MAX($AL6,IF($AJ6>0,0.5*ROUNDUP(2*((X6-MIN($W6:$AI6))/(MAX($W6:$AI6)-MIN($W6:$AI6))*($AM6-$AL6+IF(R6>10,1,0))+$AL6),0),0))),"") | AP6: =IF(Y6<>"",MIN($AM6,MAX($AL6,IF($AJ6>0,0.5*ROUNDUP(2*((Y6-MIN($W6:$AI6))/(MAX($W6:$AI6)-MIN($W6:$AI6))*($AM6-$AL6+IF(S6>10,1,0))+$AL6),0),0))),"") | AQ6: =IF(Z6<>"",MIN($AM6,MAX($AL6,IF($AJ6>0,0.5*ROUNDUP(2*((Z6-MIN($W6:$AI6))/(MAX($W6:$AI6)-MIN($W6:$AI6))*($AM6-$AL6+IF(T6>10,1,0))+$AL6),0),0))),"") | AR6: =IF(AA6<>"",MIN($AM6,MAX($AL6,IF($AJ6>0,0.5*ROUNDUP(2*((AA6-MIN($W6:$AI6))/(MAX($W6:$AI6)-MIN($W6:$AI6))*($AM6-$AL6+IF(U6>10,1,0))+$AL6),0),0))),"") | AS6: =IF(AB6<>"",MIN($AM6,MAX($AL6,IF($AJ6>0,0.5*ROUNDUP(2*((AB6-MIN($W6:$AI6))/(MAX($W6:$AI6)-MIN($W6:$AI6))*($AM6-$AL6+IF(V6>10,1,0))+$AL6),0),0))),"") | AT6: =IF(AC6<>"",MIN($AM6,MAX($AL6,IF($AJ6>0,0.5*ROUNDUP(2*((AC6-MIN($W6:$AI6))/(MAX($W6:$AI6)-MIN($W6:$AI6))*($AM6-$AL6+IF(W6>10,1,0))+$AL6),0),0))),"") | AU6: =IF(AD6<>"",MIN($AM6,MAX($AL6,IF($AJ6>0,0.5*ROUNDUP(2*((AD6-MIN($W6:$AI6))/(MAX($W6:$AI6)-MIN($W6:$AI6))*($AM6-$AL6+IF(X6>10,1,0))+$AL6),0),0))),"") | ... AZ6: =IF(AI6<>"",MIN($AM6,MAX($AL6,IF($AJ6>0,0.5*ROUNDUP(2*((AI6-MIN($W6:$AI6))/(MAX($W6:$AI6)-MIN($W6:$AI6))*($AM6-$AL6+IF(AC6>10,1,0))+$AL6),0),0))),"") | BA6: =IF(ISNUMBER(AJ6),ROUND(2*AVERAGE(AN6:AZ6),0)/2,"")
R7: =ROUNDDOWN(2*(SUMPRODUCT(C$4:P$4,C7:P7)/SUM(C$4:P$4)*20+Q7),0)/2 -> 0 | W7: =IF(COUNT(D7:Q7)>0,ROUND(2*SUM(N7:Q7)/7*20,0)/2,"") | X7: =IF(AND(X$3<>"",$W7<>""),ROUND(2*($R7*(COUNT($X$3:$AI$3)+1)-$W7)*X$3,0)/2,"") | Y7: =IF(AND(Y$3<>"",$W7<>""),ROUND(2*($R7*(COUNT($X$3:$AI$3)+1)-$W7)*Y$3,0)/2,"") | Z7: =IF(AND(Z$3<>"",$W7<>""),ROUND(2*($R7*(COUNT($X$3:$AI$3)+1)-$W7)*Z$3,0)/2,"") | AA7: =IF(AND(AA$3<>"",$W7<>""),ROUND(2*($R7*(COUNT($X$3:$AI$3)+1)-$W7)*AA$3,0)/2,"") | AB7: =IF(AND(AB$3<>"",$W7<>""),ROUND(2*($R7*(COUNT($X$3:$AI$3)+1)-$W7)*AB$3,0)/2,"") | AC7: =IF(AND(AC$3<>"",$W7<>""),ROUND(2*($R7*(COUNT($X$3:$AI$3)+1)-$W7)*AC$3,0)/2,"") | AD7: =IF(AND(AD$3<>"",$W7<>""),ROUND(2*($R7*(COUNT($X$3:$AI$3)+1)-$W7)*AD$3,0)/2,"") | AE7: =IF(AND(AE$3<>"",$W7<>""),ROUND(2*($R7*(COUNT($X$3:$AI$3)+1)-$W7)*AE$3,0)/2,"") | ... AI7: =IF(AND(AI$3<>"",$W7<>""),ROUND(2*($R7*(COUNT($X$3:$AI$3)+1)-$W7)*AI$3,0)/2,"") | AJ7: =IF(COUNT(W7:AI7)>0,ROUND(2*AVERAGE(W7:AE7),0)/2,"") | AL7: =IF(R7<10,MAX(0,2*R7-10),MAX(10,2*R7-20)) -> 0 | AM7: =2*R7-AL7 -> 0 | AN7: =IF(W7<>"",MIN($AM7,MAX($AL7,IF($AJ7>0,0.5*ROUNDUP(2*((W7-MIN($W7:$AI7))/(MAX($W7:$AI7)-MIN($W7:$AI7))*($AM7-$AL7+IF(Q7>10,1,0))+$AL7),0),0))),"") | AO7: =IF(X7<>"",MIN($AM7,MAX($AL7,IF($AJ7>0,0.5*ROUNDUP(2*((X7-MIN($W7:$AI7))/(MAX($W7:$AI7)-MIN($W7:$AI7))*($AM7-$AL7+IF(R7>10,1,0))+$AL7),0),0))),"") | AP7: =IF(Y7<>"",MIN($AM7,MAX($AL7,IF($AJ7>0,0.5*ROUNDUP(2*((Y7-MIN($W7:$AI7))/(MAX($W7:$AI7)-MIN($W7:$AI7))*($AM7-$AL7+IF(S7>10,1,0))+$AL7),0),0))),"") | AQ7: =IF(Z7<>"",MIN($AM7,MAX($AL7,IF($AJ7>0,0.5*ROUNDUP(2*((Z7-MIN($W7:$AI7))/(MAX($W7:$AI7)-MIN($W7:$AI7))*($AM7-$AL7+IF(T7>10,1,0))+$AL7),0),0))),"") | AR7: =IF(AA7<>"",MIN($AM7,MAX($AL7,IF($AJ7>0,0.5*ROUNDUP(2*((AA7-MIN($W7:$AI7))/(MAX($W7:$AI7)-MIN($W7:$AI7))*($AM7-$AL7+IF(U7>10,1,0))+$AL7),0),0))),"") | AS7: =IF(AB7<>"",MIN($AM7,MAX($AL7,IF($AJ7>0,0.5*ROUNDUP(2*((AB7-MIN($W7:$AI7))/(MAX($W7:$AI7)-MIN($W7:$AI7))*($AM7-$AL7+IF(V7>10,1,0))+$AL7),0),0))),"") | AT7: =IF(AC7<>"",MIN($AM7,MAX($AL7,IF($AJ7>0,0.5*ROUNDUP(2*((AC7-MIN($W7:$AI7))/(MAX($W7:$AI7)-MIN($W7:$AI7))*($AM7-$AL7+IF(W7>10,1,0))+$AL7),0),0))),"") | AU7: =IF(AD7<>"",MIN($AM7,MAX($AL7,IF($AJ7>0,0.5*ROUNDUP(2*((AD7-MIN($W7:$AI7))/(MAX($W7:$AI7)-MIN($W7:$AI7))*($AM7-$AL7+IF(X7>10,1,0))+$AL7),0),0))),"") | ... AZ7: =IF(AI7<>"",MIN($AM7,MAX($AL7,IF($AJ7>0,0.5*ROUNDUP(2*((AI7-MIN($W7:$AI7))/(MAX($W7:$AI7)-MIN($W7:$AI7))*($AM7-$AL7+IF(AC7>10,1,0))+$AL7),0),0))),"") | BA7: =IF(ISNUMBER(AJ7),ROUND(2*AVERAGE(AN7:AZ7),0)/2,"")
R8: =ROUNDDOWN(2*(SUMPRODUCT(C$4:P$4,C8:P8)/SUM(C$4:P$4)*20+Q8),0)/2 -> 0 | AJ8: =IF(COUNT(W8:AI8)>0,ROUND(2*AVERAGE(W8:AE8),0)/2,"") | AN8: =IF(W8<>"",MIN($AM8,MAX($AL8,IF($AJ8>0,0.5*ROUNDUP(2*((W8-MIN($W8:$AI8))/(MAX($W8:$AI8)-MIN($W8:$AI8))*($AM8-$AL8+IF(Q8>10,1,0))+$AL8),0),0))),"") | AO8: =IF(X8<>"",MIN($AM8,MAX($AL8,IF($AJ8>0,0.5*ROUNDUP(2*((X8-MIN($W8:$AI8))/(MAX($W8:$AI8)-MIN($W8:$AI8))*($AM8-$AL8+IF(R8>10,1,0))+$AL8),0),0))),"") | AP8: =IF(Y8<>"",MIN($AM8,MAX($AL8,IF($AJ8>0,0.5*ROUNDUP(2*((Y8-MIN($W8:$AI8))/(MAX($W8:$AI8)-MIN($W8:$AI8))*($AM8-$AL8+IF(S8>10,1,0))+$AL8),0),0))),"") | AQ8: =IF(Z8<>"",MIN($AM8,MAX($AL8,IF($AJ8>0,0.5*ROUNDUP(2*((Z8-MIN($W8:$AI8))/(MAX($W8:$AI8)-MIN($W8:$AI8))*($AM8-$AL8+IF(T8>10,1,0))+$AL8),0),0))),"") | AR8: =IF(AA8<>"",MIN($AM8,MAX($AL8,IF($AJ8>0,0.5*ROUNDUP(2*((AA8-MIN($W8:$AI8))/(MAX($W8:$AI8)-MIN($W8:$AI8))*($AM8-$AL8+IF(U8>10,1,0))+$AL8),0),0))),"") | AS8: =IF(AB8<>"",MIN($AM8,MAX($AL8,IF($AJ8>0,0.5*ROUNDUP(2*((AB8-MIN($W8:$AI8))/(MAX($W8:$AI8)-MIN($W8:$AI8))*($AM8-$AL8+IF(V8>10,1,0))+$AL8),0),0))),"") | AT8: =IF(AC8<>"",MIN($AM8,MAX($AL8,IF($AJ8>0,0.5*ROUNDUP(2*((AC8-MIN($W8:$AI8))/(MAX($W8:$AI8)-MIN($W8:$AI8))*($AM8-$AL8+IF(W8>10,1,0))+$AL8),0),0))),"") | AU8: =IF(AD8<>"",MIN($AM8,MAX($AL8,IF($AJ8>0,0.5*ROUNDUP(2*((AD8-MIN($W8:$AI8))/(MAX($W8:$AI8)-MIN($W8:$AI8))*($AM8-$AL8+IF(X8>10,1,0))+$AL8),0),0))),"") | ... AZ8: =IF(AI8<>"",MIN($AM8,MAX($AL8,IF($AJ8>0,0.5*ROUNDUP(2*((AI8-MIN($W8:$AI8))/(MAX($W8:$AI8)-MIN($W8:$AI8))*($AM8-$AL8+IF(AC8>10,1,0))+$AL8),0),0))),"") | BA8: =IF(ISNUMBER(AJ8),ROUND(2*AVERAGE(AN8:AZ8),0)/2,"")
R9: =ROUNDDOWN(2*(SUMPRODUCT(C$4:P$4,C9:P9)/SUM(C$4:P$4)*20+Q9),0)/2 -> 0 | W9: =IF(COUNT(D9:Q9)>0,ROUND(2*SUM(N9:Q9)/7*20,0)/2,"") | X9: =IF(AND(X$3<>"",$W9<>""),ROUND(2*($R9*(COUNT($X$3:$AI$3)+1)-$W9)*X$3,0)/2,"") | Y9: =IF(AND(Y$3<>"",$W9<>""),ROUND(2*($R9*(COUNT($X$3:$AI$3)+1)-$W9)*Y$3,0)/2,"") | Z9: =IF(AND(Z$3<>"",$W9<>""),ROUND(2*($R9*(COUNT($X$3:$AI$3)+1)-$W9)*Z$3,0)/2,"") | AA9: =IF(AND(AA$3<>"",$W9<>""),ROUND(2*($R9*(COUNT($X$3:$AI$3)+1)-$W9)*AA$3,0)/2,"") | AB9: =IF(AND(AB$3<>"",$W9<>""),ROUND(2*($R9*(COUNT($X$3:$AI$3)+1)-$W9)*AB$3,0)/2,"") | AC9: =IF(AND(AC$3<>"",$W9<>""),ROUND(2*($R9*(COUNT($X$3:$AI$3)+1)-$W9)*AC$3,0)/2,"") | AD9: =IF(AND(AD$3<>"",$W9<>""),ROUND(2*($R9*(COUNT($X$3:$AI$3)+1)-$W9)*AD$3,0)/2,"") | AE9: =IF(AND(AE$3<>"",$W9<>""),ROUND(2*($R9*(COUNT($X$3:$AI$3)+1)-$W9)*AE$3,0)/2,"") | ... AI9: =IF(AND(AI$3<>"",$W9<>""),ROUND(2*($R9*(COUNT($X$3:$AI$3)+1)-$W9)*AI$3,0)/2,"") | AJ9: =IF(COUNT(W9:AI9)>0,ROUND(2*AVERAGE(W9:AE9),0)/2,"") | AL9: =IF(R9<10,MAX(0,2*R9-10),MAX(10,2*R9-20)) -> 0 | AM9: =2*R9-AL9 -> 0 | AN9: =IF(W9<>"",MIN($AM9,MAX($AL9,IF($AJ9>0,0.5*ROUNDUP(2*((W9-MIN($W9:$AI9))/(MAX($W9:$AI9)-MIN($W9:$AI9))*($AM9-$AL9+IF(Q9>10,1,0))+$AL9),0),0))),"") | AO9: =IF(X9<>"",MIN($AM9,MAX($AL9,IF($AJ9>0,0.5*ROUNDUP(2*((X9-MIN($W9:$AI9))/(MAX($W9:$AI9)-MIN($W9:$AI9))*($AM9-$AL9+IF(R9>10,1,0))+$AL9),0),0))),"") | AP9: =IF(Y9<>"",MIN($AM9,MAX($AL9,IF($AJ9>0,0.5*ROUNDUP(2*((Y9-MIN($W9:$AI9))/(MAX($W9:$AI9)-MIN($W9:$AI9))*($AM9-$AL9+IF(S9>10,1,0))+$AL9),0),0))),"") | AQ9: =IF(Z9<>"",MIN($AM9,MAX($AL9,IF($AJ9>0,0.5*ROUNDUP(2*((Z9-MIN($W9:$AI9))/(MAX($W9:$AI9)-MIN($W9:$AI9))*($AM9-$AL9+IF(T9>10,1,0))+$AL9),0),0))),"") | AR9: =IF(AA9<>"",MIN($AM9,MAX($AL9,IF($AJ9>0,0.5*ROUNDUP(2*((AA9-MIN($W9:$AI9))/(MAX($W9:$AI9)-MIN($W9:$AI9))*($AM9-$AL9+IF(U9>10,1,0))+$AL9),0),0))),"") | AS9: =IF(AB9<>"",MIN($AM9,MAX($AL9,IF($AJ9>0,0.5*ROUNDUP(2*((AB9-MIN($W9:$AI9))/(MAX($W9:$AI9)-MIN($W9:$AI9))*($AM9-$AL9+IF(V9>10,1,0))+$AL9),0),0))),"") | AT9: =IF(AC9<>"",MIN($AM9,MAX($AL9,IF($AJ9>0,0.5*ROUNDUP(2*((AC9-MIN($W9:$AI9))/(MAX($W9:$AI9)-MIN($W9:$AI9))*($AM9-$AL9+IF(W9>10,1,0))+$AL9),0),0))),"") | AU9: =IF(AD9<>"",MIN($AM9,MAX($AL9,IF($AJ9>0,0.5*ROUNDUP(2*((AD9-MIN($W9:$AI9))/(MAX($W9:$AI9)-MIN($W9:$AI9))*($AM9-$AL9+IF(X9>10,1,0))+$AL9),0),0))),"") | ... AZ9: =IF(AI9<>"",MIN($AM9,MAX($AL9,IF($AJ9>0,0.5*ROUNDUP(2*((AI9-MIN($W9:$AI9))/(MAX($W9:$AI9)-MIN($W9:$AI9))*($AM9-$AL9+IF(AC9>10,1,0))+$AL9),0),0))),"") | BA9: =IF(ISNUMBER(AJ9),ROUND(2*AVERAGE(AN9:AZ9),0)/2,"")
R10: =ROUNDDOWN(2*(SUMPRODUCT(C$4:P$4,C10:P10)/SUM(C$4:P$4)*20+Q10),0)/2 -> 0 | W10: =IF(COUNT(D10:Q10)>0,ROUND(2*SUM(N10:Q10)/7*20,0)/2,"") | X10: =IF(AND(X$3<>"",$W10<>""),ROUND(2*($R10*(COUNT($X$3:$AI$3)+1)-$W10)*X$3,0)/2,"") | Y10: =IF(AND(Y$3<>"",$W10<>""),ROUND(2*($R10*(COUNT($X$3:$AI$3)+1)-$W10)*Y$3,0)/2,"") | Z10: =IF(AND(Z$3<>"",$W10<>""),ROUND(2*($R10*(COUNT($X$3:$AI$3)+1)-$W10)*Z$3,0)/2,"") | AA10: =IF(AND(AA$3<>"",$W10<>""),ROUND(2*($R10*(COUNT($X$3:$AI$3)+1)-$W10)*AA$3,0)/2,"") | AB10: =IF(AND(AB$3<>"",$W10<>""),ROUND(2*($R10*(COUNT($X$3:$AI$3)+1)-$W10)*AB$3,0)/2,"") | AC10: =IF(AND(AC$3<>"",$W10<>""),ROUND(2*($R10*(COUNT($X$3:$AI$3)+1)-$W10)*AC$3,0)/2,"") | AD10: =IF(AND(AD$3<>"",$W10<>""),ROUND(2*($R10*(COUNT($X$3:$AI$3)+1)-$W10)*AD$3,0)/2,"") | AE10: =IF(AND(AE$3<>"",$W10<>""),ROUND(2*($R10*(COUNT($X$3:$AI$3)+1)-$W10)*AE$3,0)/2,"") | ... AI10: =IF(AND(AI$3<>"",$W10<>""),ROUND(2*($R10*(COUNT($X$3:$AI$3)+1)-$W10)*AI$3,0)/2,"") | AJ10: =IF(COUNT(W10:AI10)>0,ROUND(2*AVERAGE(W10:AE10),0)/2,"") | AL10: =IF(R10<10,MAX(0,2*R10-10),MAX(10,2*R10-20)) -> 0 | AM10: =2*R10-AL10 -> 0 | AN10: =IF(W10<>"",MIN($AM10,MAX($AL10,IF($AJ10>0,0.5*ROUNDUP(2*((W10-MIN($W10:$AI10))/(MAX($W10:$AI10)-MIN($W10:$AI10))*($AM10-$AL10+IF(Q10>10,1,0))+$AL10),0),0))),"") | AO10: =IF(X10<>"",MIN($AM10,MAX($AL10,IF($AJ10>0,0.5*ROUNDUP(2*((X10-MIN($W10:$AI10))/(MAX($W10:$AI10)-MIN($W10:$AI10))*($AM10-$AL10+IF(R10>10,1,0))+$AL10),0),0))),"") | AP10: =IF(Y10<>"",MIN($AM10,MAX($AL10,IF($AJ10>0,0.5*ROUNDUP(2*((Y10-MIN($W10:$AI10))/(MAX($W10:$AI10)-MIN($W10:$AI10))*($AM10-$AL10+IF(S10>10,1,0))+$AL10),0),0))),"") | AQ10: =IF(Z10<>"",MIN($AM10,MAX($AL10,IF($AJ10>0,0.5*ROUNDUP(2*((Z10-MIN($W10:$AI10))/(MAX($W10:$AI10)-MIN($W10:$AI10))*($AM10-$AL10+IF(T10>10,1,0))+$AL10),0),0))),"") | AR10: =IF(AA10<>"",MIN($AM10,MAX($AL10,IF($AJ10>0,0.5*ROUNDUP(2*((AA10-MIN($W10:$AI10))/(MAX($W10:$AI10)-MIN($W10:$AI10))*($AM10-$AL10+IF(U10>10,1,0))+$AL10),0),0))),"") | AS10: =IF(AB10<>"",MIN($AM10,MAX($AL10,IF($AJ10>0,0.5*ROUNDUP(2*((AB10-MIN($W10:$AI10))/(MAX($W10:$AI10)-MIN($W10:$AI10))*($AM10-$AL10+IF(V10>10,1,0))+$AL10),0),0))),"") | AT10: =IF(AC10<>"",MIN($AM10,MAX($AL10,IF($AJ10>0,0.5*ROUNDUP(2*((AC10-MIN($W10:$AI10))/(MAX($W10:$AI10)-MIN($W10:$AI10))*($AM10-$AL10+IF(W10>10,1,0))+$AL10),0),0))),"") | AU10: =IF(AD10<>"",MIN($AM10,MAX($AL10,IF($AJ10>0,0.5*ROUNDUP(2*((AD10-MIN($W10:$AI10))/(MAX($W10:$AI10)-MIN($W10:$AI10))*($AM10-$AL10+IF(X10>10,1,0))+$AL10),0),0))),"") | ... AZ10: =IF(AI10<>"",MIN($AM10,MAX($AL10,IF($AJ10>0,0.5*ROUNDUP(2*((AI10-MIN($W10:$AI10))/(MAX($W10:$AI10)-MIN($W10:$AI10))*($AM10-$AL10+IF(AC10>10,1,0))+$AL10),0),0))),"") | BA10: =IF(ISNUMBER(AJ10),ROUND(2*AVERAGE(AN10:AZ10),0)/2,"")
A11: 2 | R11: =ROUNDDOWN(2*(SUMPRODUCT(C$4:P$4,C11:P11)/SUM(C$4:P$4)*20+Q11),0)/2 -> 0 | W11: =IF(COUNT(D11:Q11)>0,ROUND(2*SUM(N11:Q11)/7*20,0)/2,"") | X11: =IF(AND(X$3<>"",$W11<>""),ROUND(2*($R11*(COUNT($X$3:$AI$3)+1)-$W11)*X$3,0)/2,"") | Y11: =IF(AND(Y$3<>"",$W11<>""),ROUND(2*($R11*(COUNT($X$3:$AI$3)+1)-$W11)*Y$3,0)/2,"") | Z11: =IF(AND(Z$3<>"",$W11<>""),ROUND(2*($R11*(COUNT($X$3:$AI$3)+1)-$W11)*Z$3,0)/2,"") | AA11: =IF(AND(AA$3<>"",$W11<>""),ROUND(2*($R11*(COUNT($X$3:$AI$3)+1)-$W11)*AA$3,0)/2,"") | AB11: =IF(AND(AB$3<>"",$W11<>""),ROUND(2*($R11*(COUNT($X$3:$AI$3)+1)-$W11)*AB$3,0)/2,"") | AC11: =IF(AND(AC$3<>"",$W11<>""),ROUND(2*($R11*(COUNT($X$3:$AI$3)+1)-$W11)*AC$3,0)/2,"") | AD11: =IF(AND(AD$3<>"",$W11<>""),ROUND(2*($R11*(COUNT($X$3:$AI$3)+1)-$W11)*AD$3,0)/2,"") | AE11: =IF(AND(AE$3<>"",$W11<>""),ROUND(2*($R11*(COUNT($X$3:$AI$3)+1)-$W11)*AE$3,0)/2,"") | ... AI11: =IF(AND(AI$3<>"",$W11<>""),ROUND(2*($R11*(COUNT($X$3:$AI$3)+1)-$W11)*AI$3,0)/2,"") | AJ11: =IF(COUNT(W11:AI11)>0,ROUND(2*AVERAGE(W11:AE11),0)/2,"") | AL11: =IF(R11<10,MAX(0,2*R11-10),MAX(10,2*R11-20)) -> 0 | AM11: =2*R11-AL11 -> 0 | AN11: =IF(W11<>"",MIN($AM11,MAX($AL11,IF($AJ11>0,0.5*ROUNDUP(2*((W11-MIN($W11:$AI11))/(MAX($W11:$AI11)-MIN($W11:$AI11))*($AM11-$AL11+IF(Q11>10,1,0))+$AL11),0),0))),"") | AO11: =IF(X11<>"",MIN($AM11,MAX($AL11,IF($AJ11>0,0.5*ROUNDUP(2*((X11-MIN($W11:$AI11))/(MAX($W11:$AI11)-MIN($W11:$AI11))*($AM11-$AL11+IF(R11>10,1,0))+$AL11),0),0))),"") | AP11: =IF(Y11<>"",MIN($AM11,MAX($AL11,IF($AJ11>0,0.5*ROUNDUP(2*((Y11-MIN($W11:$AI11))/(MAX($W11:$AI11)-MIN($W11:$AI11))*($AM11-$AL11+IF(S11>10,1,0))+$AL11),0),0))),"") | AQ11: =IF(Z11<>"",MIN($AM11,MAX($AL11,IF($AJ11>0,0.5*ROUNDUP(2*((Z11-MIN($W11:$AI11))/(MAX($W11:$AI11)-MIN($W11:$AI11))*($AM11-$AL11+IF(T11>10,1,0))+$AL11),0),0))),"") | AR11: =IF(AA11<>"",MIN($AM11,MAX($AL11,IF($AJ11>0,0.5*ROUNDUP(2*((AA11-MIN($W11:$AI11))/(MAX($W11:$AI11)-MIN($W11:$AI11))*($AM11-$AL11+IF(U11>10,1,0))+$AL11),0),0))),"") | AS11: =IF(AB11<>"",MIN($AM11,MAX($AL11,IF($AJ11>0,0.5*ROUNDUP(2*((AB11-MIN($W11:$AI11))/(MAX($W11:$AI11)-MIN($W11:$AI11))*($AM11-$AL11+IF(V11>10,1,0))+$AL11),0),0))),"") | AT11: =IF(AC11<>"",MIN($AM11,MAX($AL11,IF($AJ11>0,0.5*ROUNDUP(2*((AC11-MIN($W11:$AI11))/(MAX($W11:$AI11)-MIN($W11:$AI11))*($AM11-$AL11+IF(W11>10,1,0))+$AL11),0),0))),"") | AU11: =IF(AD11<>"",MIN($AM11,MAX($AL11,IF($AJ11>0,0.5*ROUNDUP(2*((AD11-MIN($W11:$AI11))/(MAX($W11:$AI11)-MIN($W11:$AI11))*($AM11-$AL11+IF(X11>10,1,0))+$AL11),0),0))),"") | ... AZ11: =IF(AI11<>"",MIN($AM11,MAX($AL11,IF($AJ11>0,0.5*ROUNDUP(2*((AI11-MIN($W11:$AI11))/(MAX($W11:$AI11)-MIN($W11:$AI11))*($AM11-$AL11+IF(AC11>10,1,0))+$AL11),0),0))),"") | BA11: =IF(ISNUMBER(AJ11),ROUND(2*AVERAGE(AN11:AZ11),0)/2,"")
R12: =ROUNDDOWN(2*(SUMPRODUCT(C$4:P$4,C12:P12)/SUM(C$4:P$4)*20+Q12),0)/2 -> 0 | W12: =IF(COUNT(D12:Q12)>0,ROUND(2*SUM(N12:Q12)/7*20,0)/2,"") | X12: =IF(AND(X$3<>"",$W12<>""),ROUND(2*($R12*(COUNT($X$3:$AI$3)+1)-$W12)*X$3,0)/2,"") | Y12: =IF(AND(Y$3<>"",$W12<>""),ROUND(2*($R12*(COUNT($X$3:$AI$3)+1)-$W12)*Y$3,0)/2,"") | Z12: =IF(AND(Z$3<>"",$W12<>""),ROUND(2*($R12*(COUNT($X$3:$AI$3)+1)-$W12)*Z$3,0)/2,"") | AA12: =IF(AND(AA$3<>"",$W12<>""),ROUND(2*($R12*(COUNT($X$3:$AI$3)+1)-$W12)*AA$3,0)/2,"") | AB12: =IF(AND(AB$3<>"",$W12<>""),ROUND(2*($R12*(COUNT($X$3:$AI$3)+1)-$W12)*AB$3,0)/2,"") | AC12: =IF(AND(AC$3<>"",$W12<>""),ROUND(2*($R12*(COUNT($X$3:$AI$3)+1)-$W12)*AC$3,0)/2,"") | AD12: =IF(AND(AD$3<>"",$W12<>""),ROUND(2*($R12*(COUNT($X$3:$AI$3)+1)-$W12)*AD$3,0)/2,"") | AE12: =IF(AND(AE$3<>"",$W12<>""),ROUND(2*($R12*(COUNT($X$3:$AI$3)+1)-$W12)*AE$3,0)/2,"") | ... AI12: =IF(AND(AI$3<>"",$W12<>""),ROUND(2*($R12*(COUNT($X$3:$AI$3)+1)-$W12)*AI$3,0)/2,"") | AJ12: =IF(COUNT(W12:AI12)>0,ROUND(2*AVERAGE(W12:AE12),0)/2,"") | AL12: =IF(R12<10,MAX(0,2*R12-10),MAX(10,2*R12-20)) -> 0 | AM12: =2*R12-AL12 -> 0 | AN12: =IF(W12<>"",MIN($AM12,MAX($AL12,IF($AJ12>0,0.5*ROUNDUP(2*((W12-MIN($W12:$AI12))/(MAX($W12:$AI12)-MIN($W12:$AI12))*($AM12-$AL12+IF(Q12>10,1,0))+$AL12),0),0))),"") | AO12: =IF(X12<>"",MIN($AM12,MAX($AL12,IF($AJ12>0,0.5*ROUNDUP(2*((X12-MIN($W12:$AI12))/(MAX($W12:$AI12)-MIN($W12:$AI12))*($AM12-$AL12+IF(R12>10,1,0))+$AL12),0),0))),"") | AP12: =IF(Y12<>"",MIN($AM12,MAX($AL12,IF($AJ12>0,0.5*ROUNDUP(2*((Y12-MIN($W12:$AI12))/(MAX($W12:$AI12)-MIN($W12:$AI12))*($AM12-$AL12+IF(S12>10,1,0))+$AL12),0),0))),"") | AQ12: =IF(Z12<>"",MIN($AM12,MAX($AL12,IF($AJ12>0,0.5*ROUNDUP(2*((Z12-MIN($W12:$AI12))/(MAX($W12:$AI12)-MIN($W12:$AI12))*($AM12-$AL12+IF(T12>10,1,0))+$AL12),0),0))),"") | AR12: =IF(AA12<>"",MIN($AM12,MAX($AL12,IF($AJ12>0,0.5*ROUNDUP(2*((AA12-MIN($W12:$AI12))/(MAX($W12:$AI12)-MIN($W12:$AI12))*($AM12-$AL12+IF(U12>10,1,0))+$AL12),0),0))),"") | AS12: =IF(AB12<>"",MIN($AM12,MAX($AL12,IF($AJ12>0,0.5*ROUNDUP(2*((AB12-MIN($W12:$AI12))/(MAX($W12:$AI12)-MIN($W12:$AI12))*($AM12-$AL12+IF(V12>10,1,0))+$AL12),0),0))),"") | AT12: =IF(AC12<>"",MIN($AM12,MAX($AL12,IF($AJ12>0,0.5*ROUNDUP(2*((AC12-MIN($W12:$AI12))/(MAX($W12:$AI12)-MIN($W12:$AI12))*($AM12-$AL12+IF(W12>10,1,0))+$AL12),0),0))),"") | AU12: =IF(AD12<>"",MIN($AM12,MAX($AL12,IF($AJ12>0,0.5*ROUNDUP(2*((AD12-MIN($W12:$AI12))/(MAX($W12:$AI12)-MIN($W12:$AI12))*($AM12-$AL12+IF(X12>10,1,0))+$AL12),0),0))),"") | ... AZ12: =IF(AI12<>"",MIN($AM12,MAX($AL12,IF($AJ12>0,0.5*ROUNDUP(2*((AI12-MIN($W12:$AI12))/(MAX($W12:$AI12)-MIN($W12:$AI12))*($AM12-$AL12+IF(AC12>10,1,0))+$AL12),0),0))),"") | BA12: =IF(ISNUMBER(AJ12),ROUND(2*AVERAGE(AN12:AZ12),0)/2,"")
R13: =ROUNDDOWN(2*(SUMPRODUCT(C$4:P$4,C13:P13)/SUM(C$4:P$4)*20+Q13),0)/2 -> 0 | W13: =IF(COUNT(D13:Q13)>0,ROUND(2*SUM(N13:Q13)/7*20,0)/2,"") | X13: =IF(AND(X$3<>"",$W13<>""),ROUND(2*($R13*(COUNT($X$3:$AI$3)+1)-$W13)*X$3,0)/2,"") | Y13: =IF(AND(Y$3<>"",$W13<>""),ROUND(2*($R13*(COUNT($X$3:$AI$3)+1)-$W13)*Y$3,0)/2,"") | Z13: =IF(AND(Z$3<>"",$W13<>""),ROUND(2*($R13*(COUNT($X$3:$AI$3)+1)-$W13)*Z$3,0)/2,"") | AA13: =IF(AND(AA$3<>"",$W13<>""),ROUND(2*($R13*(COUNT($X$3:$AI$3)+1)-$W13)*AA$3,0)/2,"") | AB13: =IF(AND(AB$3<>"",$W13<>""),ROUND(2*($R13*(COUNT($X$3:$AI$3)+1)-$W13)*AB$3,0)/2,"") | AC13: =IF(AND(AC$3<>"",$W13<>""),ROUND(2*($R13*(COUNT($X$3:$AI$3)+1)-$W13)*AC$3,0)/2,"") | AD13: =IF(AND(AD$3<>"",$W13<>""),ROUND(2*($R13*(COUNT($X$3:$AI$3)+1)-$W13)*AD$3,0)/2,"") | AE13: =IF(AND(AE$3<>"",$W13<>""),ROUND(2*($R13*(COUNT($X$3:$AI$3)+1)-$W13)*AE$3,0)/2,"") | ... AI13: =IF(AND(AI$3<>"",$W13<>""),ROUND(2*($R13*(COUNT($X$3:$AI$3)+1)-$W13)*AI$3,0)/2,"") | AJ13: =IF(COUNT(W13:AI13)>0,ROUND(2*AVERAGE(W13:AE13),0)/2,"") | AL13: =IF(R13<10,MAX(0,2*R13-10),MAX(10,2*R13-20)) -> 0 | AM13: =2*R13-AL13 -> 0 | AN13: =IF(W13<>"",MIN($AM13,MAX($AL13,IF($AJ13>0,0.5*ROUNDUP(2*((W13-MIN($W13:$AI13))/(MAX($W13:$AI13)-MIN($W13:$AI13))*($AM13-$AL13+IF(Q13>10,1,0))+$AL13),0),0))),"") | AO13: =IF(X13<>"",MIN($AM13,MAX($AL13,IF($AJ13>0,0.5*ROUNDUP(2*((X13-MIN($W13:$AI13))/(MAX($W13:$AI13)-MIN($W13:$AI13))*($AM13-$AL13+IF(R13>10,1,0))+$AL13),0),0))),"") | AP13: =IF(Y13<>"",MIN($AM13,MAX($AL13,IF($AJ13>0,0.5*ROUNDUP(2*((Y13-MIN($W13:$AI13))/(MAX($W13:$AI13)-MIN($W13:$AI13))*($AM13-$AL13+IF(S13>10,1,0))+$AL13),0),0))),"") | AQ13: =IF(Z13<>"",MIN($AM13,MAX($AL13,IF($AJ13>0,0.5*ROUNDUP(2*((Z13-MIN($W13:$AI13))/(MAX($W13:$AI13)-MIN($W13:$AI13))*($AM13-$AL13+IF(T13>10,1,0))+$AL13),0),0))),"") | AR13: =IF(AA13<>"",MIN($AM13,MAX($AL13,IF($AJ13>0,0.5*ROUNDUP(2*((AA13-MIN($W13:$AI13))/(MAX($W13:$AI13)-MIN($W13:$AI13))*($AM13-$AL13+IF(U13>10,1,0))+$AL13),0),0))),"") | AS13: =IF(AB13<>"",MIN($AM13,MAX($AL13,IF($AJ13>0,0.5*ROUNDUP(2*((AB13-MIN($W13:$AI13))/(MAX($W13:$AI13)-MIN($W13:$AI13))*($AM13-$AL13+IF(V13>10,1,0))+$AL13),0),0))),"") | AT13: =IF(AC13<>"",MIN($AM13,MAX($AL13,IF($AJ13>0,0.5*ROUNDUP(2*((AC13-MIN($W13:$AI13))/(MAX($W13:$AI13)-MIN($W13:$AI13))*($AM13-$AL13+IF(W13>10,1,0))+$AL13),0),0))),"") | AU13: =IF(AD13<>"",MIN($AM13,MAX($AL13,IF($AJ13>0,0.5*ROUNDUP(2*((AD13-MIN($W13:$AI13))/(MAX($W13:$AI13)-MIN($W13:$AI13))*($AM13-$AL13+IF(X13>10,1,0))+$AL13),0),0))),"") | ... AZ13: =IF(AI13<>"",MIN($AM13,MAX($AL13,IF($AJ13>0,0.5*ROUNDUP(2*((AI13-MIN($W13:$AI13))/(MAX($W13:$AI13)-MIN($W13:$AI13))*($AM13-$AL13+IF(AC13>10,1,0))+$AL13),0),0))),"") | BA13: =IF(ISNUMBER(AJ13),ROUND(2*AVERAGE(AN13:AZ13),0)/2,"")
R14: =ROUNDDOWN(2*(SUMPRODUCT(C$4:P$4,C14:P14)/SUM(C$4:P$4)*20+Q14),0)/2 -> 0 | W14: =IF(COUNT(D14:Q14)>0,ROUND(2*SUM(N14:Q14)/7*20,0)/2,"") | X14: =IF(AND(X$3<>"",$W14<>""),ROUND(2*($R14*(COUNT($X$3:$AI$3)+1)-$W14)*X$3,0)/2,"") | Y14: =IF(AND(Y$3<>"",$W14<>""),ROUND(2*($R14*(COUNT($X$3:$AI$3)+1)-$W14)*Y$3,0)/2,"") | Z14: =IF(AND(Z$3<>"",$W14<>""),ROUND(2*($R14*(COUNT($X$3:$AI$3)+1)-$W14)*Z$3,0)/2,"") | AA14: =IF(AND(AA$3<>"",$W14<>""),ROUND(2*($R14*(COUNT($X$3:$AI$3)+1)-$W14)*AA$3,0)/2,"") | AB14: =IF(AND(AB$3<>"",$W14<>""),ROUND(2*($R14*(COUNT($X$3:$AI$3)+1)-$W14)*AB$3,0)/2,"") | AC14: =IF(AND(AC$3<>"",$W14<>""),ROUND(2*($R14*(COUNT($X$3:$AI$3)+1)-$W14)*AC$3,0)/2,"") | AD14: =IF(AND(AD$3<>"",$W14<>""),ROUND(2*($R14*(COUNT($X$3:$AI$3)+1)-$W14)*AD$3,0)/2,"") | AE14: =IF(AND(AE$3<>"",$W14<>""),ROUND(2*($R14*(COUNT($X$3:$AI$3)+1)-$W14)*AE$3,0)/2,"") | ... AI14: =IF(AND(AI$3<>"",$W14<>""),ROUND(2*($R14*(COUNT($X$3:$AI$3)+1)-$W14)*AI$3,0)/2,"") | AJ14: =IF(COUNT(W14:AI14)>0,ROUND(2*AVERAGE(W14:AE14),0)/2,"") | AL14: =IF(R14<10,MAX(0,2*R14-10),MAX(10,2*R14-20)) -> 0 | AM14: =2*R14-AL14 -> 0 | AN14: =IF(W14<>"",MIN($AM14,MAX($AL14,IF($AJ14>0,0.5*ROUNDUP(2*((W14-MIN($W14:$AI14))/(MAX($W14:$AI14)-MIN($W14:$AI14))*($AM14-$AL14+IF(Q14>10,1,0))+$AL14),0),0))),"") | AO14: =IF(X14<>"",MIN($AM14,MAX($AL14,IF($AJ14>0,0.5*ROUNDUP(2*((X14-MIN($W14:$AI14))/(MAX($W14:$AI14)-MIN($W14:$AI14))*($AM14-$AL14+IF(R14>10,1,0))+$AL14),0),0))),"") | AP14: =IF(Y14<>"",MIN($AM14,MAX($AL14,IF($AJ14>0,0.5*ROUNDUP(2*((Y14-MIN($W14:$AI14))/(MAX($W14:$AI14)-MIN($W14:$AI14))*($AM14-$AL14+IF(S14>10,1,0))+$AL14),0),0))),"") | AQ14: =IF(Z14<>"",MIN($AM14,MAX($AL14,IF($AJ14>0,0.5*ROUNDUP(2*((Z14-MIN($W14:$AI14))/(MAX($W14:$AI14)-MIN($W14:$AI14))*($AM14-$AL14+IF(T14>10,1,0))+$AL14),0),0))),"") | AR14: =IF(AA14<>"",MIN($AM14,MAX($AL14,IF($AJ14>0,0.5*ROUNDUP(2*((AA14-MIN($W14:$AI14))/(MAX($W14:$AI14)-MIN($W14:$AI14))*($AM14-$AL14+IF(U14>10,1,0))+$AL14),0),0))),"") | AS14: =IF(AB14<>"",MIN($AM14,MAX($AL14,IF($AJ14>0,0.5*ROUNDUP(2*((AB14-MIN($W14:$AI14))/(MAX($W14:$AI14)-MIN($W14:$AI14))*($AM14-$AL14+IF(V14>10,1,0))+$AL14),0),0))),"") | AT14: =IF(AC14<>"",MIN($AM14,MAX($AL14,IF($AJ14>0,0.5*ROUNDUP(2*((AC14-MIN($W14:$AI14))/(MAX($W14:$AI14)-MIN($W14:$AI14))*($AM14-$AL14+IF(W14>10,1,0))+$AL14),0),0))),"") | AU14: =IF(AD14<>"",MIN($AM14,MAX($AL14,IF($AJ14>0,0.5*ROUNDUP(2*((AD14-MIN($W14:$AI14))/(MAX($W14:$AI14)-MIN($W14:$AI14))*($AM14-$AL14+IF(X14>10,1,0))+$AL14),0),0))),"") | ... AZ14: =IF(AI14<>"",MIN($AM14,MAX($AL14,IF($AJ14>0,0.5*ROUNDUP(2*((AI14-MIN($W14:$AI14))/(MAX($W14:$AI14)-MIN($W14:$AI14))*($AM14-$AL14+IF(AC14>10,1,0))+$AL14),0),0))),"") | BA14: =IF(ISNUMBER(AJ14),ROUND(2*AVERAGE(AN14:AZ14),0)/2,"")
R15: =ROUNDDOWN(2*(SUMPRODUCT(C$4:P$4,C15:P15)/SUM(C$4:P$4)*20+Q15),0)/2 -> 0 | W15: =IF(COUNT(D15:Q15)>0,ROUND(2*SUM(N15:Q15)/7*20,0)/2,"") | X15: =IF(AND(X$3<>"",$W15<>""),ROUND(2*($R15*(COUNT($X$3:$AI$3)+1)-$W15)*X$3,0)/2,"") | Y15: =IF(AND(Y$3<>"",$W15<>""),ROUND(2*($R15*(COUNT($X$3:$AI$3)+1)-$W15)*Y$3,0)/2,"") | Z15: =IF(AND(Z$3<>"",$W15<>""),ROUND(2*($R15*(COUNT($X$3:$AI$3)+1)-$W15)*Z$3,0)/2,"") | AA15: =IF(AND(AA$3<>"",$W15<>""),ROUND(2*($R15*(COUNT($X$3:$AI$3)+1)-$W15)*AA$3,0)/2,"") | AB15: =IF(AND(AB$3<>"",$W15<>""),ROUND(2*($R15*(COUNT($X$3:$AI$3)+1)-$W15)*AB$3,0)/2,"") | AC15: =IF(AND(AC$3<>"",$W15<>""),ROUND(2*($R15*(COUNT($X$3:$AI$3)+1)-$W15)*AC$3,0)/2,"") | AD15: =IF(AND(AD$3<>"",$W15<>""),ROUND(2*($R15*(COUNT($X$3:$AI$3)+1)-$W15)*AD$3,0)/2,"") | AE15: =IF(AND(AE$3<>"",$W15<>""),ROUND(2*($R15*(COUNT($X$3:$AI$3)+1)-$W15)*AE$3,0)/2,"") | ... AI15: =IF(AND(AI$3<>"",$W15<>""),ROUND(2*($R15*(COUNT($X$3:$AI$3)+1)-$W15)*AI$3,0)/2,"") | AJ15: =IF(COUNT(W15:AI15)>0,ROUND(2*AVERAGE(W15:AE15),0)/2,"") | AL15: =IF(R15<10,MAX(0,2*R15-10),MAX(10,2*R15-20)) -> 0 | AM15: =2*R15-AL15 -> 0 | AN15: =IF(W15<>"",MIN($AM15,MAX($AL15,IF($AJ15>0,0.5*ROUNDUP(2*((W15-MIN($W15:$AI15))/(MAX($W15:$AI15)-MIN($W15:$AI15))*($AM15-$AL15+IF(Q15>10,1,0))+$AL15),0),0))),"") | AO15: =IF(X15<>"",MIN($AM15,MAX($AL15,IF($AJ15>0,0.5*ROUNDUP(2*((X15-MIN($W15:$AI15))/(MAX($W15:$AI15)-MIN($W15:$AI15))*($AM15-$AL15+IF(R15>10,1,0))+$AL15),0),0))),"") | AP15: =IF(Y15<>"",MIN($AM15,MAX($AL15,IF($AJ15>0,0.5*ROUNDUP(2*((Y15-MIN($W15:$AI15))/(MAX($W15:$AI15)-MIN($W15:$AI15))*($AM15-$AL15+IF(S15>10,1,0))+$AL15),0),0))),"") | AQ15: =IF(Z15<>"",MIN($AM15,MAX($AL15,IF($AJ15>0,0.5*ROUNDUP(2*((Z15-MIN($W15:$AI15))/(MAX($W15:$AI15)-MIN($W15:$AI15))*($AM15-$AL15+IF(T15>10,1,0))+$AL15),0),0))),"") | AR15: =IF(AA15<>"",MIN($AM15,MAX($AL15,IF($AJ15>0,0.5*ROUNDUP(2*((AA15-MIN($W15:$AI15))/(MAX($W15:$AI15)-MIN($W15:$AI15))*($AM15-$AL15+IF(U15>10,1,0))+$AL15),0),0))),"") | AS15: =IF(AB15<>"",MIN($AM15,MAX($AL15,IF($AJ15>0,0.5*ROUNDUP(2*((AB15-MIN($W15:$AI15))/(MAX($W15:$AI15)-MIN($W15:$AI15))*($AM15-$AL15+IF(V15>10,1,0))+$AL15),0),0))),"") | AT15: =IF(AC15<>"",MIN($AM15,MAX($AL15,IF($AJ15>0,0.5*ROUNDUP(2*((AC15-MIN($W15:$AI15))/(MAX($W15:$AI15)-MIN($W15:$AI15))*($AM15-$AL15+IF(W15>10,1,0))+$AL15),0),0))),"") | AU15: =IF(AD15<>"",MIN($AM15,MAX($AL15,IF($AJ15>0,0.5*ROUNDUP(2*((AD15-MIN($W15:$AI15))/(MAX($W15:$AI15)-MIN($W15:$AI15))*($AM15-$AL15+IF(X15>10,1,0))+$AL15),0),0))),"") | ... AZ15: =IF(AI15<>"",MIN($AM15,MAX($AL15,IF($AJ15>0,0.5*ROUNDUP(2*((AI15-MIN($W15:$AI15))/(MAX($W15:$AI15)-MIN($W15:$AI15))*($AM15-$AL15+IF(AC15>10,1,0))+$AL15),0),0))),"") | BA15: =IF(ISNUMBER(AJ15),ROUND(2*AVERAGE(AN15:AZ15),0)/2,"")
R16: =ROUNDDOWN(2*(SUMPRODUCT(C$4:P$4,C16:P16)/SUM(C$4:P$4)*20+Q16),0)/2 -> 0 | W16: =IF(COUNT(D16:Q16)>0,ROUND(2*SUM(N16:Q16)/7*20,0)/2,"") | X16: =IF(AND(X$3<>"",$W16<>""),ROUND(2*($R16*(COUNT($X$3:$AI$3)+1)-$W16)*X$3,0)/2,"") | Y16: =IF(AND(Y$3<>"",$W16<>""),ROUND(2*($R16*(COUNT($X$3:$AI$3)+1)-$W16)*Y$3,0)/2,"") | Z16: =IF(AND(Z$3<>"",$W16<>""),ROUND(2*($R16*(COUNT($X$3:$AI$3)+1)-$W16)*Z$3,0)/2,"") | AA16: =IF(AND(AA$3<>"",$W16<>""),ROUND(2*($R16*(COUNT($X$3:$AI$3)+1)-$W16)*AA$3,0)/2,"") | AB16: =IF(AND(AB$3<>"",$W16<>""),ROUND(2*($R16*(COUNT($X$3:$AI$3)+1)-$W16)*AB$3,0)/2,"") | AC16: =IF(AND(AC$3<>"",$W16<>""),ROUND(2*($R16*(COUNT($X$3:$AI$3)+1)-$W16)*AC$3,0)/2,"") | AD16: =IF(AND(AD$3<>"",$W16<>""),ROUND(2*($R16*(COUNT($X$3:$AI$3)+1)-$W16)*AD$3,0)/2,"") | AE16: =IF(AND(AE$3<>"",$W16<>""),ROUND(2*($R16*(COUNT($X$3:$AI$3)+1)-$W16)*AE$3,0)/2,"") | ... AI16: =IF(AND(AI$3<>"",$W16<>""),ROUND(2*($R16*(COUNT($X$3:$AI$3)+1)-$W16)*AI$3,0)/2,"") | AJ16: =IF(COUNT(W16:AI16)>0,ROUND(2*AVERAGE(W16:AE16),0)/2,"") | AL16: =IF(R16<10,MAX(0,2*R16-10),MAX(10,2*R16-20)) -> 0 | AM16: =2*R16-AL16 -> 0 | AN16: =IF(W16<>"",MIN($AM16,MAX($AL16,IF($AJ16>0,0.5*ROUNDUP(2*((W16-MIN($W16:$AI16))/(MAX($W16:$AI16)-MIN($W16:$AI16))*($AM16-$AL16+IF(Q16>10,1,0))+$AL16),0),0))),"") | AO16: =IF(X16<>"",MIN($AM16,MAX($AL16,IF($AJ16>0,0.5*ROUNDUP(2*((X16-MIN($W16:$AI16))/(MAX($W16:$AI16)-MIN($W16:$AI16))*($AM16-$AL16+IF(R16>10,1,0))+$AL16),0),0))),"") | AP16: =IF(Y16<>"",MIN($AM16,MAX($AL16,IF($AJ16>0,0.5*ROUNDUP(2*((Y16-MIN($W16:$AI16))/(MAX($W16:$AI16)-MIN($W16:$AI16))*($AM16-$AL16+IF(S16>10,1,0))+$AL16),0),0))),"") | AQ16: =IF(Z16<>"",MIN($AM16,MAX($AL16,IF($AJ16>0,0.5*ROUNDUP(2*((Z16-MIN($W16:$AI16))/(MAX($W16:$AI16)-MIN($W16:$AI16))*($AM16-$AL16+IF(T16>10,1,0))+$AL16),0),0))),"") | AR16: =IF(AA16<>"",MIN($AM16,MAX($AL16,IF($AJ16>0,0.5*ROUNDUP(2*((AA16-MIN($W16:$AI16))/(MAX($W16:$AI16)-MIN($W16:$AI16))*($AM16-$AL16+IF(U16>10,1,0))+$AL16),0),0))),"") | AS16: =IF(AB16<>"",MIN($AM16,MAX($AL16,IF($AJ16>0,0.5*ROUNDUP(2*((AB16-MIN($W16:$AI16))/(MAX($W16:$AI16)-MIN($W16:$AI16))*($AM16-$AL16+IF(V16>10,1,0))+$AL16),0),0))),"") | AT16: =IF(AC16<>"",MIN($AM16,MAX($AL16,IF($AJ16>0,0.5*ROUNDUP(2*((AC16-MIN($W16:$AI16))/(MAX($W16:$AI16)-MIN($W16:$AI16))*($AM16-$AL16+IF(W16>10,1,0))+$AL16),0),0))),"") | AU16: =IF(AD16<>"",MIN($AM16,MAX($AL16,IF($AJ16>0,0.5*ROUNDUP(2*((AD16-MIN($W16:$AI16))/(MAX($W16:$AI16)-MIN($W16:$AI16))*($AM16-$AL16+IF(X16>10,1,0))+$AL16),0),0))),"") | ... AZ16: =IF(AI16<>"",MIN($AM16,MAX($AL16,IF($AJ16>0,0.5*ROUNDUP(2*((AI16-MIN($W16:$AI16))/(MAX($W16:$AI16)-MIN($W16:$AI16))*($AM16-$AL16+IF(AC16>10,1,0))+$AL16),0),0))),"") | BA16: =IF(ISNUMBER(AJ16),ROUND(2*AVERAGE(AN16:AZ16),0)/2,"")
A17: 3 | R17: =ROUNDDOWN(2*(SUMPRODUCT(C$4:P$4,C17:P17)/SUM(C$4:P$4)*20+Q17),0)/2 -> 0 | W17: =IF(COUNT(D17:Q17)>0,ROUND(2*SUM(N17:Q17)/7*20,0)/2,"") | X17: =IF(AND(X$3<>"",$W17<>""),ROUND(2*($R17*(COUNT($X$3:$AI$3)+1)-$W17)*X$3,0)/2,"") | Y17: =IF(AND(Y$3<>"",$W17<>""),ROUND(2*($R17*(COUNT($X$3:$AI$3)+1)-$W17)*Y$3,0)/2,"") | Z17: =IF(AND(Z$3<>"",$W17<>""),ROUND(2*($R17*(COUNT($X$3:$AI$3)+1)-$W17)*Z$3,0)/2,"") | AA17: =IF(AND(AA$3<>"",$W17<>""),ROUND(2*($R17*(COUNT($X$3:$AI$3)+1)-$W17)*AA$3,0)/2,"") | AB17: =IF(AND(AB$3<>"",$W17<>""),ROUND(2*($R17*(COUNT($X$3:$AI$3)+1)-$W17)*AB$3,0)/2,"") | AC17: =IF(AND(AC$3<>"",$W17<>""),ROUND(2*($R17*(COUNT($X$3:$AI$3)+1)-$W17)*AC$3,0)/2,"") | AD17: =IF(AND(AD$3<>"",$W17<>""),ROUND(2*($R17*(COUNT($X$3:$AI$3)+1)-$W17)*AD$3,0)/2,"") | AE17: =IF(AND(AE$3<>"",$W17<>""),ROUND(2*($R17*(COUNT($X$3:$AI$3)+1)-$W17)*AE$3,0)/2,"") | ... AI17: =IF(AND(AI$3<>"",$W17<>""),ROUND(2*($R17*(COUNT($X$3:$AI$3)+1)-$W17)*AI$3,0)/2,"") | AJ17: =IF(COUNT(W17:AI17)>0,ROUND(2*AVERAGE(W17:AE17),0)/2,"") | AL17: =IF(R17<10,MAX(0,2*R17-10),MAX(10,2*R17-20)) -> 0 | AM17: =2*R17-AL17 -> 0 | AN17: =IF(W17<>"",MIN($AM17,MAX($AL17,IF($AJ17>0,0.5*ROUNDUP(2*((W17-MIN($W17:$AI17))/(MAX($W17:$AI17)-MIN($W17:$AI17))*($AM17-$AL17+IF(Q17>10,1,0))+$AL17),0),0))),"") | AO17: =IF(X17<>"",MIN($AM17,MAX($AL17,IF($AJ17>0,0.5*ROUNDUP(2*((X17-MIN($W17:$AI17))/(MAX($W17:$AI17)-MIN($W17:$AI17))*($AM17-$AL17+IF(R17>10,1,0))+$AL17),0),0))),"") | AP17: =IF(Y17<>"",MIN($AM17,MAX($AL17,IF($AJ17>0,0.5*ROUNDUP(2*((Y17-MIN($W17:$AI17))/(MAX($W17:$AI17)-MIN($W17:$AI17))*($AM17-$AL17+IF(S17>10,1,0))+$AL17),0),0))),"") | AQ17: =IF(Z17<>"",MIN($AM17,MAX($AL17,IF($AJ17>0,0.5*ROUNDUP(2*((Z17-MIN($W17:$AI17))/(MAX($W17:$AI17)-MIN($W17:$AI17))*($AM17-$AL17+IF(T17>10,1,0))+$AL17),0),0))),"") | AR17: =IF(AA17<>"",MIN($AM17,MAX($AL17,IF($AJ17>0,0.5*ROUNDUP(2*((AA17-MIN($W17:$AI17))/(MAX($W17:$AI17)-MIN($W17:$AI17))*($AM17-$AL17+IF(U17>10,1,0))+$AL17),0),0))),"") | AS17: =IF(AB17<>"",MIN($AM17,MAX($AL17,IF($AJ17>0,0.5*ROUNDUP(2*((AB17-MIN($W17:$AI17))/(MAX($W17:$AI17)-MIN($W17:$AI17))*($AM17-$AL17+IF(V17>10,1,0))+$AL17),0),0))),"") | AT17: =IF(AC17<>"",MIN($AM17,MAX($AL17,IF($AJ17>0,0.5*ROUNDUP(2*((AC17-MIN($W17:$AI17))/(MAX($W17:$AI17)-MIN($W17:$AI17))*($AM17-$AL17+IF(W17>10,1,0))+$AL17),0),0))),"") | AU17: =IF(AD17<>"",MIN($AM17,MAX($AL17,IF($AJ17>0,0.5*ROUNDUP(2*((AD17-MIN($W17:$AI17))/(MAX($W17:$AI17)-MIN($W17:$AI17))*($AM17-$AL17+IF(X17>10,1,0))+$AL17),0),0))),"") | ... AZ17: =IF(AI17<>"",MIN($AM17,MAX($AL17,IF($AJ17>0,0.5*ROUNDUP(2*((AI17-MIN($W17:$AI17))/(MAX($W17:$AI17)-MIN($W17:$AI17))*($AM17-$AL17+IF(AC17>10,1,0))+$AL17),0),0))),"") | BA17: =IF(ISNUMBER(AJ17),ROUND(2*AVERAGE(AN17:AZ17),0)/2,"")
R18: =ROUNDDOWN(2*(SUMPRODUCT(C$4:P$4,C18:P18)/SUM(C$4:P$4)*20+Q18),0)/2 -> 0 | W18: =IF(COUNT(D18:Q18)>0,ROUND(2*SUM(N18:Q18)/7*20,0)/2,"") | X18: =IF(AND(X$3<>"",$W18<>""),ROUND(2*($R18*(COUNT($X$3:$AI$3)+1)-$W18)*X$3,0)/2,"") | Y18: =IF(AND(Y$3<>"",$W18<>""),ROUND(2*($R18*(COUNT($X$3:$AI$3)+1)-$W18)*Y$3,0)/2,"") | Z18: =IF(AND(Z$3<>"",$W18<>""),ROUND(2*($R18*(COUNT($X$3:$AI$3)+1)-$W18)*Z$3,0)/2,"") | AA18: =IF(AND(AA$3<>"",$W18<>""),ROUND(2*($R18*(COUNT($X$3:$AI$3)+1)-$W18)*AA$3,0)/2,"") | AB18: =IF(AND(AB$3<>"",$W18<>""),ROUND(2*($R18*(COUNT($X$3:$AI$3)+1)-$W18)*AB$3,0)/2,"") | AC18: =IF(AND(AC$3<>"",$W18<>""),ROUND(2*($R18*(COUNT($X$3:$AI$3)+1)-$W18)*AC$3,0)/2,"") | AD18: =IF(AND(AD$3<>"",$W18<>""),ROUND(2*($R18*(COUNT($X$3:$AI$3)+1)-$W18)*AD$3,0)/2,"") | AE18: =IF(AND(AE$3<>"",$W18<>""),ROUND(2*($R18*(COUNT($X$3:$AI$3)+1)-$W18)*AE$3,0)/2,"") | ... AI18: =IF(AND(AI$3<>"",$W18<>""),ROUND(2*($R18*(COUNT($X$3:$AI$3)+1)-$W18)*AI$3,0)/2,"") | AJ18: =IF(COUNT(W18:AI18)>0,ROUND(2*AVERAGE(W18:AE18),0)/2,"") | AL18: =IF(R18<10,MAX(0,2*R18-10),MAX(10,2*R18-20)) -> 0 | AM18: =2*R18-AL18 -> 0 | AN18: =IF(W18<>"",MIN($AM18,MAX($AL18,IF($AJ18>0,0.5*ROUNDUP(2*((W18-MIN($W18:$AI18))/(MAX($W18:$AI18)-MIN($W18:$AI18))*($AM18-$AL18+IF(Q18>10,1,0))+$AL18),0),0))),"") | AO18: =IF(X18<>"",MIN($AM18,MAX($AL18,IF($AJ18>0,0.5*ROUNDUP(2*((X18-MIN($W18:$AI18))/(MAX($W18:$AI18)-MIN($W18:$AI18))*($AM18-$AL18+IF(R18>10,1,0))+$AL18),0),0))),"") | AP18: =IF(Y18<>"",MIN($AM18,MAX($AL18,IF($AJ18>0,0.5*ROUNDUP(2*((Y18-MIN($W18:$AI18))/(MAX($W18:$AI18)-MIN($W18:$AI18))*($AM18-$AL18+IF(S18>10,1,0))+$AL18),0),0))),"") | AQ18: =IF(Z18<>"",MIN($AM18,MAX($AL18,IF($AJ18>0,0.5*ROUNDUP(2*((Z18-MIN($W18:$AI18))/(MAX($W18:$AI18)-MIN($W18:$AI18))*($AM18-$AL18+IF(T18>10,1,0))+$AL18),0),0))),"") | AR18: =IF(AA18<>"",MIN($AM18,MAX($AL18,IF($AJ18>0,0.5*ROUNDUP(2*((AA18-MIN($W18:$AI18))/(MAX($W18:$AI18)-MIN($W18:$AI18))*($AM18-$AL18+IF(U18>10,1,0))+$AL18),0),0))),"") | AS18: =IF(AB18<>"",MIN($AM18,MAX($AL18,IF($AJ18>0,0.5*ROUNDUP(2*((AB18-MIN($W18:$AI18))/(MAX($W18:$AI18)-MIN($W18:$AI18))*($AM18-$AL18+IF(V18>10,1,0))+$AL18),0),0))),"") | AT18: =IF(AC18<>"",MIN($AM18,MAX($AL18,IF($AJ18>0,0.5*ROUNDUP(2*((AC18-MIN($W18:$AI18))/(MAX($W18:$AI18)-MIN($W18:$AI18))*($AM18-$AL18+IF(W18>10,1,0))+$AL18),0),0))),"") | AU18: =IF(AD18<>"",MIN($AM18,MAX($AL18,IF($AJ18>0,0.5*ROUNDUP(2*((AD18-MIN($W18:$AI18))/(MAX($W18:$AI18)-MIN($W18:$AI18))*($AM18-$AL18+IF(X18>10,1,0))+$AL18),0),0))),"") | ... AZ18: =IF(AI18<>"",MIN($AM18,MAX($AL18,IF($AJ18>0,0.5*ROUNDUP(2*((AI18-MIN($W18:$AI18))/(MAX($W18:$AI18)-MIN($W18:$AI18))*($AM18-$AL18+IF(AC18>10,1,0))+$AL18),0),0))),"") | BA18: =IF(ISNUMBER(AJ18),ROUND(2*AVERAGE(AN18:AZ18),0)/2,"")
R19: =ROUNDDOWN(2*(SUMPRODUCT(C$4:P$4,C19:P19)/SUM(C$4:P$4)*20+Q19),0)/2 -> 0 | W19: =IF(COUNT(D19:Q19)>0,ROUND(2*SUM(N19:Q19)/7*20,0)/2,"") | X19: =IF(AND(X$3<>"",$W19<>""),ROUND(2*($R19*(COUNT($X$3:$AI$3)+1)-$W19)*X$3,0)/2,"") | Y19: =IF(AND(Y$3<>"",$W19<>""),ROUND(2*($R19*(COUNT($X$3:$AI$3)+1)-$W19)*Y$3,0)/2,"") | Z19: =IF(AND(Z$3<>"",$W19<>""),ROUND(2*($R19*(COUNT($X$3:$AI$3)+1)-$W19)*Z$3,0)/2,"") | AA19: =IF(AND(AA$3<>"",$W19<>""),ROUND(2*($R19*(COUNT($X$3:$AI$3)+1)-$W19)*AA$3,0)/2,"") | AB19: =IF(AND(AB$3<>"",$W19<>""),ROUND(2*($R19*(COUNT($X$3:$AI$3)+1)-$W19)*AB$3,0)/2,"") | AC19: =IF(AND(AC$3<>"",$W19<>""),ROUND(2*($R19*(COUNT($X$3:$AI$3)+1)-$W19)*AC$3,0)/2,"") | AD19: =IF(AND(AD$3<>"",$W19<>""),ROUND(2*($R19*(COUNT($X$3:$AI$3)+1)-$W19)*AD$3,0)/2,"") | AE19: =IF(AND(AE$3<>"",$W19<>""),ROUND(2*($R19*(COUNT($X$3:$AI$3)+1)-$W19)*AE$3,0)/2,"") | ... AI19: =IF(AND(AI$3<>"",$W19<>""),ROUND(2*($R19*(COUNT($X$3:$AI$3)+1)-$W19)*AI$3,0)/2,"") | AJ19: =IF(COUNT(W19:AI19)>0,ROUND(2*AVERAGE(W19:AE19),0)/2,"") | AL19: =IF(R19<10,MAX(0,2*R19-10),MAX(10,2*R19-20)) -> 0 | AM19: =2*R19-AL19 -> 0 | AN19: =IF(W19<>"",MIN($AM19,MAX($AL19,IF($AJ19>0,0.5*ROUNDUP(2*((W19-MIN($W19:$AI19))/(MAX($W19:$AI19)-MIN($W19:$AI19))*($AM19-$AL19+IF(Q19>10,1,0))+$AL19),0),0))),"") | AO19: =IF(X19<>"",MIN($AM19,MAX($AL19,IF($AJ19>0,0.5*ROUNDUP(2*((X19-MIN($W19:$AI19))/(MAX($W19:$AI19)-MIN($W19:$AI19))*($AM19-$AL19+IF(R19>10,1,0))+$AL19),0),0))),"") | AP19: =IF(Y19<>"",MIN($AM19,MAX($AL19,IF($AJ19>0,0.5*ROUNDUP(2*((Y19-MIN($W19:$AI19))/(MAX($W19:$AI19)-MIN($W19:$AI19))*($AM19-$AL19+IF(S19>10,1,0))+$AL19),0),0))),"") | AQ19: =IF(Z19<>"",MIN($AM19,MAX($AL19,IF($AJ19>0,0.5*ROUNDUP(2*((Z19-MIN($W19:$AI19))/(MAX($W19:$AI19)-MIN($W19:$AI19))*($AM19-$AL19+IF(T19>10,1,0))+$AL19),0),0))),"") | AR19: =IF(AA19<>"",MIN($AM19,MAX($AL19,IF($AJ19>0,0.5*ROUNDUP(2*((AA19-MIN($W19:$AI19))/(MAX($W19:$AI19)-MIN($W19:$AI19))*($AM19-$AL19+IF(U19>10,1,0))+$AL19),0),0))),"") | AS19: =IF(AB19<>"",MIN($AM19,MAX($AL19,IF($AJ19>0,0.5*ROUNDUP(2*((AB19-MIN($W19:$AI19))/(MAX($W19:$AI19)-MIN($W19:$AI19))*($AM19-$AL19+IF(V19>10,1,0))+$AL19),0),0))),"") | AT19: =IF(AC19<>"",MIN($AM19,MAX($AL19,IF($AJ19>0,0.5*ROUNDUP(2*((AC19-MIN($W19:$AI19))/(MAX($W19:$AI19)-MIN($W19:$AI19))*($AM19-$AL19+IF(W19>10,1,0))+$AL19),0),0))),"") | AU19: =IF(AD19<>"",MIN($AM19,MAX($AL19,IF($AJ19>0,0.5*ROUNDUP(2*((AD19-MIN($W19:$AI19))/(MAX($W19:$AI19)-MIN($W19:$AI19))*($AM19-$AL19+IF(X19>10,1,0))+$AL19),0),0))),"") | ... AZ19: =IF(AI19<>"",MIN($AM19,MAX($AL19,IF($AJ19>0,0.5*ROUNDUP(2*((AI19-MIN($W19:$AI19))/(MAX($W19:$AI19)-MIN($W19:$AI19))*($AM19-$AL19+IF(AC19>10,1,0))+$AL19),0),0))),"") | BA19: =IF(ISNUMBER(AJ19),ROUND(2*AVERAGE(AN19:AZ19),0)/2,"")
R20: =ROUNDDOWN(2*(SUMPRODUCT(C$4:P$4,C20:P20)/SUM(C$4:P$4)*20+Q20),0)/2 -> 0 | W20: =IF(COUNT(D20:Q20)>0,ROUND(2*SUM(N20:Q20)/7*20,0)/2,"") | X20: =IF(AND(X$3<>"",$W20<>""),ROUND(2*($R20*(COUNT($X$3:$AI$3)+1)-$W20)*X$3,0)/2,"") | Y20: =IF(AND(Y$3<>"",$W20<>""),ROUND(2*($R20*(COUNT($X$3:$AI$3)+1)-$W20)*Y$3,0)/2,"") | Z20: =IF(AND(Z$3<>"",$W20<>""),ROUND(2*($R20*(COUNT($X$3:$AI$3)+1)-$W20)*Z$3,0)/2,"") | AA20: =IF(AND(AA$3<>"",$W20<>""),ROUND(2*($R20*(COUNT($X$3:$AI$3)+1)-$W20)*AA$3,0)/2,"") | AB20: =IF(AND(AB$3<>"",$W20<>""),ROUND(2*($R20*(COUNT($X$3:$AI$3)+1)-$W20)*AB$3,0)/2,"") | AC20: =IF(AND(AC$3<>"",$W20<>""),ROUND(2*($R20*(COUNT($X$3:$AI$3)+1)-$W20)*AC$3,0)/2,"") | AD20: =IF(AND(AD$3<>"",$W20<>""),ROUND(2*($R20*(COUNT($X$3:$AI$3)+1)-$W20)*AD$3,0)/2,"") | AE20: =IF(AND(AE$3<>"",$W20<>""),ROUND(2*($R20*(COUNT($X$3:$AI$3)+1)-$W20)*AE$3,0)/2,"") | ... AI20: =IF(AND(AI$3<>"",$W20<>""),ROUND(2*($R20*(COUNT($X$3:$AI$3)+1)-$W20)*AI$3,0)/2,"") | AJ20: =IF(COUNT(W20:AI20)>0,ROUND(2*AVERAGE(W20:AE20),0)/2,"") | AL20: =IF(R20<10,MAX(0,2*R20-10),MAX(10,2*R20-20)) -> 0 | AM20: =2*R20-AL20 -> 0 | AN20: =IF(W20<>"",MIN($AM20,MAX($AL20,IF($AJ20>0,0.5*ROUNDUP(2*((W20-MIN($W20:$AI20))/(MAX($W20:$AI20)-MIN($W20:$AI20))*($AM20-$AL20+IF(Q20>10,1,0))+$AL20),0),0))),"") | AO20: =IF(X20<>"",MIN($AM20,MAX($AL20,IF($AJ20>0,0.5*ROUNDUP(2*((X20-MIN($W20:$AI20))/(MAX($W20:$AI20)-MIN($W20:$AI20))*($AM20-$AL20+IF(R20>10,1,0))+$AL20),0),0))),"") | AP20: =IF(Y20<>"",MIN($AM20,MAX($AL20,IF($AJ20>0,0.5*ROUNDUP(2*((Y20-MIN($W20:$AI20))/(MAX($W20:$AI20)-MIN($W20:$AI20))*($AM20-$AL20+IF(S20>10,1,0))+$AL20),0),0))),"") | AQ20: =IF(Z20<>"",MIN($AM20,MAX($AL20,IF($AJ20>0,0.5*ROUNDUP(2*((Z20-MIN($W20:$AI20))/(MAX($W20:$AI20)-MIN($W20:$AI20))*($AM20-$AL20+IF(T20>10,1,0))+$AL20),0),0))),"") | AR20: =IF(AA20<>"",MIN($AM20,MAX($AL20,IF($AJ20>0,0.5*ROUNDUP(2*((AA20-MIN($W20:$AI20))/(MAX($W20:$AI20)-MIN($W20:$AI20))*($AM20-$AL20+IF(U20>10,1,0))+$AL20),0),0))),"") | AS20: =IF(AB20<>"",MIN($AM20,MAX($AL20,IF($AJ20>0,0.5*ROUNDUP(2*((AB20-MIN($W20:$AI20))/(MAX($W20:$AI20)-MIN($W20:$AI20))*($AM20-$AL20+IF(V20>10,1,0))+$AL20),0),0))),"") | AT20: =IF(AC20<>"",MIN($AM20,MAX($AL20,IF($AJ20>0,0.5*ROUNDUP(2*((AC20-MIN($W20:$AI20))/(MAX($W20:$AI20)-MIN($W20:$AI20))*($AM20-$AL20+IF(W20>10,1,0))+$AL20),0),0))),"") | AU20: =IF(AD20<>"",MIN($AM20,MAX($AL20,IF($AJ20>0,0.5*ROUNDUP(2*((AD20-MIN($W20:$AI20))/(MAX($W20:$AI20)-MIN($W20:$AI20))*($AM20-$AL20+IF(X20>10,1,0))+$AL20),0),0))),"") | ... AZ20: =IF(AI20<>"",MIN($AM20,MAX($AL20,IF($AJ20>0,0.5*ROUNDUP(2*((AI20-MIN($W20:$AI20))/(MAX($W20:$AI20)-MIN($W20:$AI20))*($AM20-$AL20+IF(AC20>10,1,0))+$AL20),0),0))),"") | BA20: =IF(ISNUMBER(AJ20),ROUND(2*AVERAGE(AN20:AZ20),0)/2,"")
R21: =ROUNDDOWN(2*(SUMPRODUCT(C$4:P$4,C21:P21)/SUM(C$4:P$4)*20+Q21),0)/2 -> 0 | W21: =IF(COUNT(D21:Q21)>0,ROUND(2*SUM(N21:Q21)/7*20,0)/2,"") | X21: =IF(AND(X$3<>"",$W21<>""),ROUND(2*($R21*(COUNT($X$3:$AI$3)+1)-$W21)*X$3,0)/2,"") | Y21: =IF(AND(Y$3<>"",$W21<>""),ROUND(2*($R21*(COUNT($X$3:$AI$3)+1)-$W21)*Y$3,0)/2,"") | Z21: =IF(AND(Z$3<>"",$W21<>""),ROUND(2*($R21*(COUNT($X$3:$AI$3)+1)-$W21)*Z$3,0)/2,"") | AA21: =IF(AND(AA$3<>"",$W21<>""),ROUND(2*($R21*(COUNT($X$3:$AI$3)+1)-$W21)*AA$3,0)/2,"") | AB21: =IF(AND(AB$3<>"",$W21<>""),ROUND(2*($R21*(COUNT($X$3:$AI$3)+1)-$W21)*AB$3,0)/2,"") | AC21: =IF(AND(AC$3<>"",$W21<>""),ROUND(2*($R21*(COUNT($X$3:$AI$3)+1)-$W21)*AC$3,0)/2,"") | AD21: =IF(AND(AD$3<>"",$W21<>""),ROUND(2*($R21*(COUNT($X$3:$AI$3)+1)-$W21)*AD$3,0)/2,"") | AE21: =IF(AND(AE$3<>"",$W21<>""),ROUND(2*($R21*(COUNT($X$3:$AI$3)+1)-$W21)*AE$3,0)/2,"") | ... AI21: =IF(AND(AI$3<>"",$W21<>""),ROUND(2*($R21*(COUNT($X$3:$AI$3)+1)-$W21)*AI$3,0)/2,"") | AJ21: =IF(COUNT(W21:AI21)>0,ROUND(2*AVERAGE(W21:AE21),0)/2,"") | AL21: =IF(R21<10,MAX(0,2*R21-10),MAX(10,2*R21-20)) -> 0 | AM21: =2*R21-AL21 -> 0 | AN21: =IF(W21<>"",MIN($AM21,MAX($AL21,IF($AJ21>0,0.5*ROUNDUP(2*((W21-MIN($W21:$AI21))/(MAX($W21:$AI21)-MIN($W21:$AI21))*($AM21-$AL21+IF(Q21>10,1,0))+$AL21),0),0))),"") | AO21: =IF(X21<>"",MIN($AM21,MAX($AL21,IF($AJ21>0,0.5*ROUNDUP(2*((X21-MIN($W21:$AI21))/(MAX($W21:$AI21)-MIN($W21:$AI21))*($AM21-$AL21+IF(R21>10,1,0))+$AL21),0),0))),"") | AP21: =IF(Y21<>"",MIN($AM21,MAX($AL21,IF($AJ21>0,0.5*ROUNDUP(2*((Y21-MIN($W21:$AI21))/(MAX($W21:$AI21)-MIN($W21:$AI21))*($AM21-$AL21+IF(S21>10,1,0))+$AL21),0),0))),"") | AQ21: =IF(Z21<>"",MIN($AM21,MAX($AL21,IF($AJ21>0,0.5*ROUNDUP(2*((Z21-MIN($W21:$AI21))/(MAX($W21:$AI21)-MIN($W21:$AI21))*($AM21-$AL21+IF(T21>10,1,0))+$AL21),0),0))),"") | AR21: =IF(AA21<>"",MIN($AM21,MAX($AL21,IF($AJ21>0,0.5*ROUNDUP(2*((AA21-MIN($W21:$AI21))/(MAX($W21:$AI21)-MIN($W21:$AI21))*($AM21-$AL21+IF(U21>10,1,0))+$AL21),0),0))),"") | AS21: =IF(AB21<>"",MIN($AM21,MAX($AL21,IF($AJ21>0,0.5*ROUNDUP(2*((AB21-MIN($W21:$AI21))/(MAX($W21:$AI21)-MIN($W21:$AI21))*($AM21-$AL21+IF(V21>10,1,0))+$AL21),0),0))),"") | AT21: =IF(AC21<>"",MIN($AM21,MAX($AL21,IF($AJ21>0,0.5*ROUNDUP(2*((AC21-MIN($W21:$AI21))/(MAX($W21:$AI21)-MIN($W21:$AI21))*($AM21-$AL21+IF(W21>10,1,0))+$AL21),0),0))),"") | AU21: =IF(AD21<>"",MIN($AM21,MAX($AL21,IF($AJ21>0,0.5*ROUNDUP(2*((AD21-MIN($W21:$AI21))/(MAX($W21:$AI21)-MIN($W21:$AI21))*($AM21-$AL21+IF(X21>10,1,0))+$AL21),0),0))),"") | ... AZ21: =IF(AI21<>"",MIN($AM21,MAX($AL21,IF($AJ21>0,0.5*ROUNDUP(2*((AI21-MIN($W21:$AI21))/(MAX($W21:$AI21)-MIN($W21:$AI21))*($AM21-$AL21+IF(AC21>10,1,0))+$AL21),0),0))),"") | BA21: =IF(ISNUMBER(AJ21),ROUND(2*AVERAGE(AN21:AZ21),0)/2,"")
R22: =ROUNDDOWN(2*(SUMPRODUCT(C$4:P$4,C22:P22)/SUM(C$4:P$4)*20+Q22),0)/2 -> 0 | W22: =IF(COUNT(D22:Q22)>0,ROUND(2*SUM(N22:Q22)/7*20,0)/2,"") | X22: =IF(AND(X$3<>"",$W22<>""),ROUND(2*($R22*(COUNT($X$3:$AI$3)+1)-$W22)*X$3,0)/2,"") | Y22: =IF(AND(Y$3<>"",$W22<>""),ROUND(2*($R22*(COUNT($X$3:$AI$3)+1)-$W22)*Y$3,0)/2,"") | Z22: =IF(AND(Z$3<>"",$W22<>""),ROUND(2*($R22*(COUNT($X$3:$AI$3)+1)-$W22)*Z$3,0)/2,"") | AA22: =IF(AND(AA$3<>"",$W22<>""),ROUND(2*($R22*(COUNT($X$3:$AI$3)+1)-$W22)*AA$3,0)/2,"") | AB22: =IF(AND(AB$3<>"",$W22<>""),ROUND(2*($R22*(COUNT($X$3:$AI$3)+1)-$W22)*AB$3,0)/2,"") | AC22: =IF(AND(AC$3<>"",$W22<>""),ROUND(2*($R22*(COUNT($X$3:$AI$3)+1)-$W22)*AC$3,0)/2,"") | AD22: =IF(AND(AD$3<>"",$W22<>""),ROUND(2*($R22*(COUNT($X$3:$AI$3)+1)-$W22)*AD$3,0)/2,"") | AE22: =IF(AND(AE$3<>"",$W22<>""),ROUND(2*($R22*(COUNT($X$3:$AI$3)+1)-$W22)*AE$3,0)/2,"") | ... AI22: =IF(AND(AI$3<>"",$W22<>""),ROUND(2*($R22*(COUNT($X$3:$AI$3)+1)-$W22)*AI$3,0)/2,"") | AJ22: =IF(COUNT(W22:AI22)>0,ROUND(2*AVERAGE(W22:AE22),0)/2,"") | AL22: =IF(R22<10,MAX(0,2*R22-10),MAX(10,2*R22-20)) -> 0 | AM22: =2*R22-AL22 -> 0 | AN22: =IF(W22<>"",MIN($AM22,MAX($AL22,IF($AJ22>0,0.5*ROUNDUP(2*((W22-MIN($W22:$AI22))/(MAX($W22:$AI22)-MIN($W22:$AI22))*($AM22-$AL22+IF(Q22>10,1,0))+$AL22),0),0))),"") | AO22: =IF(X22<>"",MIN($AM22,MAX($AL22,IF($AJ22>0,0.5*ROUNDUP(2*((X22-MIN($W22:$AI22))/(MAX($W22:$AI22)-MIN($W22:$AI22))*($AM22-$AL22+IF(R22>10,1,0))+$AL22),0),0))),"") | AP22: =IF(Y22<>"",MIN($AM22,MAX($AL22,IF($AJ22>0,0.5*ROUNDUP(2*((Y22-MIN($W22:$AI22))/(MAX($W22:$AI22)-MIN($W22:$AI22))*($AM22-$AL22+IF(S22>10,1,0))+$AL22),0),0))),"") | AQ22: =IF(Z22<>"",MIN($AM22,MAX($AL22,IF($AJ22>0,0.5*ROUNDUP(2*((Z22-MIN($W22:$AI22))/(MAX($W22:$AI22)-MIN($W22:$AI22))*($AM22-$AL22+IF(T22>10,1,0))+$AL22),0),0))),"") | AR22: =IF(AA22<>"",MIN($AM22,MAX($AL22,IF($AJ22>0,0.5*ROUNDUP(2*((AA22-MIN($W22:$AI22))/(MAX($W22:$AI22)-MIN($W22:$AI22))*($AM22-$AL22+IF(U22>10,1,0))+$AL22),0),0))),"") | AS22: =IF(AB22<>"",MIN($AM22,MAX($AL22,IF($AJ22>0,0.5*ROUNDUP(2*((AB22-MIN($W22:$AI22))/(MAX($W22:$AI22)-MIN($W22:$AI22))*($AM22-$AL22+IF(V22>10,1,0))+$AL22),0),0))),"") | AT22: =IF(AC22<>"",MIN($AM22,MAX($AL22,IF($AJ22>0,0.5*ROUNDUP(2*((AC22-MIN($W22:$AI22))/(MAX($W22:$AI22)-MIN($W22:$AI22))*($AM22-$AL22+IF(W22>10,1,0))+$AL22),0),0))),"") | AU22: =IF(AD22<>"",MIN($AM22,MAX($AL22,IF($AJ22>0,0.5*ROUNDUP(2*((AD22-MIN($W22:$AI22))/(MAX($W22:$AI22)-MIN($W22:$AI22))*($AM22-$AL22+IF(X22>10,1,0))+$AL22),0),0))),"") | ... AZ22: =IF(AI22<>"",MIN($AM22,MAX($AL22,IF($AJ22>0,0.5*ROUNDUP(2*((AI22-MIN($W22:$AI22))/(MAX($W22:$AI22)-MIN($W22:$AI22))*($AM22-$AL22+IF(AC22>10,1,0))+$AL22),0),0))),"") | BA22: =IF(ISNUMBER(AJ22),ROUND(2*AVERAGE(AN22:AZ22),0)/2,"")
A23: 4 | R23: =ROUNDDOWN(2*(SUMPRODUCT(C$4:P$4,C23:P23)/SUM(C$4:P$4)*20+Q23),0)/2 -> 0 | W23: =IF(COUNT(D23:Q23)>0,ROUND(2*SUM(N23:Q23)/7*20,0)/2,"") | X23: =IF(AND(X$3<>"",$W23<>""),ROUND(2*($R23*(COUNT($X$3:$AI$3)+1)-$W23)*X$3,0)/2,"") | Y23: =IF(AND(Y$3<>"",$W23<>""),ROUND(2*($R23*(COUNT($X$3:$AI$3)+1)-$W23)*Y$3,0)/2,"") | Z23: =IF(AND(Z$3<>"",$W23<>""),ROUND(2*($R23*(COUNT($X$3:$AI$3)+1)-$W23)*Z$3,0)/2,"") | AA23: =IF(AND(AA$3<>"",$W23<>""),ROUND(2*($R23*(COUNT($X$3:$AI$3)+1)-$W23)*AA$3,0)/2,"") | AB23: =IF(AND(AB$3<>"",$W23<>""),ROUND(2*($R23*(COUNT($X$3:$AI$3)+1)-$W23)*AB$3,0)/2,"") | AC23: =IF(AND(AC$3<>"",$W23<>""),ROUND(2*($R23*(COUNT($X$3:$AI$3)+1)-$W23)*AC$3,0)/2,"") | AD23: =IF(AND(AD$3<>"",$W23<>""),ROUND(2*($R23*(COUNT($X$3:$AI$3)+1)-$W23)*AD$3,0)/2,"") | AE23: =IF(AND(AE$3<>"",$W23<>""),ROUND(2*($R23*(COUNT($X$3:$AI$3)+1)-$W23)*AE$3,0)/2,"") | ... AI23: =IF(AND(AI$3<>"",$W23<>""),ROUND(2*($R23*(COUNT($X$3:$AI$3)+1)-$W23)*AI$3,0)/2,"") | AJ23: =IF(COUNT(W23:AI23)>0,ROUND(2*AVERAGE(W23:AE23),0)/2,"") | AL23: =IF(R23<10,MAX(0,2*R23-10),MAX(10,2*R23-20)) -> 0 | AM23: =2*R23-AL23 -> 0 | AN23: =IF(W23<>"",MIN($AM23,MAX($AL23,IF($AJ23>0,0.5*ROUNDUP(2*((W23-MIN($W23:$AI23))/(MAX($W23:$AI23)-MIN($W23:$AI23))*($AM23-$AL23+IF(Q23>10,1,0))+$AL23),0),0))),"") | AO23: =IF(X23<>"",MIN($AM23,MAX($AL23,IF($AJ23>0,0.5*ROUNDUP(2*((X23-MIN($W23:$AI23))/(MAX($W23:$AI23)-MIN($W23:$AI23))*($AM23-$AL23+IF(R23>10,1,0))+$AL23),0),0))),"") | AP23: =IF(Y23<>"",MIN($AM23,MAX($AL23,IF($AJ23>0,0.5*ROUNDUP(2*((Y23-MIN($W23:$AI23))/(MAX($W23:$AI23)-MIN($W23:$AI23))*($AM23-$AL23+IF(S23>10,1,0))+$AL23),0),0))),"") | AQ23: =IF(Z23<>"",MIN($AM23,MAX($AL23,IF($AJ23>0,0.5*ROUNDUP(2*((Z23-MIN($W23:$AI23))/(MAX($W23:$AI23)-MIN($W23:$AI23))*($AM23-$AL23+IF(T23>10,1,0))+$AL23),0),0))),"") | AR23: =IF(AA23<>"",MIN($AM23,MAX($AL23,IF($AJ23>0,0.5*ROUNDUP(2*((AA23-MIN($W23:$AI23))/(MAX($W23:$AI23)-MIN($W23:$AI23))*($AM23-$AL23+IF(U23>10,1,0))+$AL23),0),0))),"") | AS23: =IF(AB23<>"",MIN($AM23,MAX($AL23,IF($AJ23>0,0.5*ROUNDUP(2*((AB23-MIN($W23:$AI23))/(MAX($W23:$AI23)-MIN($W23:$AI23))*($AM23-$AL23+IF(V23>10,1,0))+$AL23),0),0))),"") | AT23: =IF(AC23<>"",MIN($AM23,MAX($AL23,IF($AJ23>0,0.5*ROUNDUP(2*((AC23-MIN($W23:$AI23))/(MAX($W23:$AI23)-MIN($W23:$AI23))*($AM23-$AL23+IF(W23>10,1,0))+$AL23),0),0))),"") | AU23: =IF(AD23<>"",MIN($AM23,MAX($AL23,IF($AJ23>0,0.5*ROUNDUP(2*((AD23-MIN($W23:$AI23))/(MAX($W23:$AI23)-MIN($W23:$AI23))*($AM23-$AL23+IF(X23>10,1,0))+$AL23),0),0))),"") | ... AZ23: =IF(AI23<>"",MIN($AM23,MAX($AL23,IF($AJ23>0,0.5*ROUNDUP(2*((AI23-MIN($W23:$AI23))/(MAX($W23:$AI23)-MIN($W23:$AI23))*($AM23-$AL23+IF(AC23>10,1,0))+$AL23),0),0))),"") | BA23: =IF(ISNUMBER(AJ23),ROUND(2*AVERAGE(AN23:AZ23),0)/2,"")
R24: =ROUNDDOWN(2*(SUMPRODUCT(C$4:P$4,C24:P24)/SUM(C$4:P$4)*20+Q24),0)/2 -> 0 | W24: =IF(COUNT(D24:Q24)>0,ROUND(2*SUM(N24:Q24)/7*20,0)/2,"") | X24: =IF(AND(X$3<>"",$W24<>""),ROUND(2*($R24*(COUNT($X$3:$AI$3)+1)-$W24)*X$3,0)/2,"") | Y24: =IF(AND(Y$3<>"",$W24<>""),ROUND(2*($R24*(COUNT($X$3:$AI$3)+1)-$W24)*Y$3,0)/2,"") | Z24: =IF(AND(Z$3<>"",$W24<>""),ROUND(2*($R24*(COUNT($X$3:$AI$3)+1)-$W24)*Z$3,0)/2,"") | AA24: =IF(AND(AA$3<>"",$W24<>""),ROUND(2*($R24*(COUNT($X$3:$AI$3)+1)-$W24)*AA$3,0)/2,"") | AB24: =IF(AND(AB$3<>"",$W24<>""),ROUND(2*($R24*(COUNT($X$3:$AI$3)+1)-$W24)*AB$3,0)/2,"") | AC24: =IF(AND(AC$3<>"",$W24<>""),ROUND(2*($R24*(COUNT($X$3:$AI$3)+1)-$W24)*AC$3,0)/2,"") | AD24: =IF(AND(AD$3<>"",$W24<>""),ROUND(2*($R24*(COUNT($X$3:$AI$3)+1)-$W24)*AD$3,0)/2,"") | AE24: =IF(AND(AE$3<>"",$W24<>""),ROUND(2*($R24*(COUNT($X$3:$AI$3)+1)-$W24)*AE$3,0)/2,"") | ... AI24: =IF(AND(AI$3<>"",$W24<>""),ROUND(2*($R24*(COUNT($X$3:$AI$3)+1)-$W24)*AI$3,0)/2,"") | AJ24: =IF(COUNT(W24:AI24)>0,ROUND(2*AVERAGE(W24:AE24),0)/2,"") | AL24: =IF(R24<10,MAX(0,2*R24-10),MAX(10,2*R24-20)) -> 0 | AM24: =2*R24-AL24 -> 0 | AN24: =IF(W24<>"",MIN($AM24,MAX($AL24,IF($AJ24>0,0.5*ROUNDUP(2*((W24-MIN($W24:$AI24))/(MAX($W24:$AI24)-MIN($W24:$AI24))*($AM24-$AL24+IF(Q24>10,1,0))+$AL24),0),0))),"") | AO24: =IF(X24<>"",MIN($AM24,MAX($AL24,IF($AJ24>0,0.5*ROUNDUP(2*((X24-MIN($W24:$AI24))/(MAX($W24:$AI24)-MIN($W24:$AI24))*($AM24-$AL24+IF(R24>10,1,0))+$AL24),0),0))),"") | AP24: =IF(Y24<>"",MIN($AM24,MAX($AL24,IF($AJ24>0,0.5*ROUNDUP(2*((Y24-MIN($W24:$AI24))/(MAX($W24:$AI24)-MIN($W24:$AI24))*($AM24-$AL24+IF(S24>10,1,0))+$AL24),0),0))),"") | AQ24: =IF(Z24<>"",MIN($AM24,MAX($AL24,IF($AJ24>0,0.5*ROUNDUP(2*((Z24-MIN($W24:$AI24))/(MAX($W24:$AI24)-MIN($W24:$AI24))*($AM24-$AL24+IF(T24>10,1,0))+$AL24),0),0))),"") | AR24: =IF(AA24<>"",MIN($AM24,MAX($AL24,IF($AJ24>0,0.5*ROUNDUP(2*((AA24-MIN($W24:$AI24))/(MAX($W24:$AI24)-MIN($W24:$AI24))*($AM24-$AL24+IF(U24>10,1,0))+$AL24),0),0))),"") | AS24: =IF(AB24<>"",MIN($AM24,MAX($AL24,IF($AJ24>0,0.5*ROUNDUP(2*((AB24-MIN($W24:$AI24))/(MAX($W24:$AI24)-MIN($W24:$AI24))*($AM24-$AL24+IF(V24>10,1,0))+$AL24),0),0))),"") | AT24: =IF(AC24<>"",MIN($AM24,MAX($AL24,IF($AJ24>0,0.5*ROUNDUP(2*((AC24-MIN($W24:$AI24))/(MAX($W24:$AI24)-MIN($W24:$AI24))*($AM24-$AL24+IF(W24>10,1,0))+$AL24),0),0))),"") | AU24: =IF(AD24<>"",MIN($AM24,MAX($AL24,IF($AJ24>0,0.5*ROUNDUP(2*((AD24-MIN($W24:$AI24))/(MAX($W24:$AI24)-MIN($W24:$AI24))*($AM24-$AL24+IF(X24>10,1,0))+$AL24),0),0))),"") | ... AZ24: =IF(AI24<>"",MIN($AM24,MAX($AL24,IF($AJ24>0,0.5*ROUNDUP(2*((AI24-MIN($W24:$AI24))/(MAX($W24:$AI24)-MIN($W24:$AI24))*($AM24-$AL24+IF(AC24>10,1,0))+$AL24),0),0))),"") | BA24: =IF(ISNUMBER(AJ24),ROUND(2*AVERAGE(AN24:AZ24),0)/2,"")
